Workbook
Name DM_ViTri: 'Danh mục'!$B$6:$B$29
Name DM_Tang: 'Danh mục'!$C$6:$C$30
Name DM_PhanLoai: 'Danh mục'!$D$6:$D$13
Name DM_CapDo: 'Danh mục'!$E$6:$E$9
Name DM_TT_PA: 'Danh mục'!$F$6:$F$9
Name DM_TT_CV: 'Danh mục'!$G$6:$G$10
Name DM_Loai: 'Danh mục'!$H$6:$H$7
Name DM_Nhom: 'Danh mục'!$I$6:$I$12
Name DM_TanSuat: 'Danh mục'!$J$6:$J$12
Name DM_TanSuatNgay: 'Danh mục'!$K$6:$K$12
Name DM_TanSuatThang: 'Danh mục'!$L$6:$L$12
Name DM_TVBQT: OFFSET('Danh mục'!$M$6,0,0,MAX(1,COUNTA('Danh mục'!$M$6:$M$20)),1)
Name DM_DonVi: OFFSET('Danh mục'!$N$6,0,0,MAX(1,COUNTA('Danh mục'!$N$6:$N$30)),1)
Name DanhSachMa: OFFSET('Danh mục'!$P$6,0,0,MAX(1,COUNTA('Phản ánh'!$A$6:$A$505)+COUNTA('Kế hoạch'!$A$6:$A$305)),1)
Name DS_PA: OFFSET('Phản ánh'!$A$6,0,0,MAX(1,COUNTA('Phản ánh'!$A$6:$A$505)),1)
Name DM_PhuTrach: OFFSET('Danh mục'!$R$6,0,0,MAX(1,COUNTA('Danh mục'!$R$6:$R$17)),1)
Name DM_ThucHien: OFFSET('Danh mục'!$V$6,0,0,MAX(1,COUNTA('Danh mục'!$V$6:$V$35)),1)
Name DM_Kenh: OFFSET('Danh mục'!$Z$6,0,0,MAX(1,COUNTA('Danh mục'!$Z$6:$Z$17)),1)
Name DM_SLA_Cap: 'Danh mục'!$AB$6:$AB$9
Name DM_SLA_Gio: 'Danh mục'!$AC$6:$AC$9
Name DM_DonViTG: 'Danh mục'!$AE$6:$AE$7
Name TDBC: 'Tổng quan'!$AH$3
Name NgayBC: INT('Tổng quan'!$AH$3)

Sheet Hướng dẫn
B1: HƯỚNG DẪN SỬ DỤNG
B2: Bảng điều hành Saigon South Residences: phản ánh cư dân và kế hoạch bảo trì, vệ sinh, cảnh quan
B4: File dùng để ghi nhận phản ánh của cư dân, lập kế hoạch vận hành và theo dõi tiến độ xử lý. Mọi con số, biểu đồ và sơ đồ ở tab Tổng quan tự thay đổi ngay khi nhập dữ liệu mới, không cần thao tác thêm.
B6: 1 | C6: Các tab trong file
C7: Tab | D7: Công dụng | E7: Người nhập
C8: Hướng dẫn | D8: Tài liệu hướng dẫn này. | E8: Chỉ đọc
C9: Tổng quan | D9: Bảng điều hành: thẻ chỉ số, tóm tắt tự động, lịch 14 ngày, 6 biểu đồ, sơ đồ 6 block, bảng theo khu vực, danh sách cần chú ý, thời gian xử lý và deadline, bảng theo người phụ trách, chi phí. | E9: Tự động; chỉ đổi Thời điểm báo cáo khi cần
C10: Báo cáo tuần | D10: Trang tóm tắt khổ A4 để in hoặc lưu PDF khi họp: chỉ số chính, việc cần chú ý, bảng theo người phụ trách, lời nhắn chưa phản hồi. Tự cập nhật. | E10: Không sửa
C11: Phản ánh | D11: Sổ ghi phản ánh: thời điểm ghi nhận, kênh, căn hộ, nội dung, vị trí, người phụ trách, người thực hiện, thời gian ước tính, deadline. | E11: Ban Quản lý, TV BQT
C12: Kế hoạch | D12: Kế hoạch bảo trì, vệ sinh, cảnh quan: việc định kỳ lặp theo tần suất và việc đột xuất, kèm người phụ trách, ước tính, dự toán và chi phí. | E12: Ban Quản lý
C13: Nhật ký tiến độ | D13: Mỗi lần cập nhật tiến độ ghi một dòng kèm thời điểm. Đây là nguồn của trạng thái, tiến độ và thời điểm xử lý xong. | E13: Người phụ trách từng việc
C14: Lời nhắn | D14: Lời nhắn của người xem gửi Ban Quản lý và phần phản hồi. Không liên kết với phản ánh, kế hoạch hay số liệu tổng quan. | E14: Người xem (cột B đến F), Ban Quản lý (cột G đến J)
C15: Danh mục | D15: Danh sách thả xuống: TV BQT, đơn vị, người phụ trách, người thực hiện, kênh tiếp nhận, thời hạn chuẩn theo cấp độ khẩn. | E15: Thư ký BQT
C16: Số liệu | D16: Bảng số tự tính để vẽ biểu đồ. | E16: Không sửa
B17: • | C17: Màu của từng tab dưới đáy cửa sổ trùng với màu ở cột Tab bên trên để dễ nhận ra.
B19: 2 | C19: Quy trình mỗi ngày
B20: 1 | C20: Có phản ánh mới: thêm một dòng ở tab Phản ánh, dùng mã ở ô Mã gợi ý tiếp theo (ô nền vàng phía trên bảng), ghi thời điểm ghi nhận, người phụ trách và người thực hiện.
B21: 2 | C21: Có việc cần làm: thêm một dòng ở tab Kế hoạch, chọn Định kỳ hoặc Đột xuất.
B22: 3 | C22: Có tiến triển: ghi một dòng mới ở tab Nhật ký tiến độ gồm thời điểm, mã, phần trăm hoàn thành và trạng thái. Dòng Đã xử lý hoặc Hoàn thành chính là thời điểm xử lý xong.
B23: 4 | C23: Mở tab Tổng quan xem số liệu đã cập nhật, dùng hai danh sách Cần chú ý và bảng Theo người phụ trách để đôn đốc.
B25: 3 | C25: Nhập phản ánh
B26: • | C26: Ô nền trắng là ô nhập. Cột có tiêu đề xám tự tính, không gõ đè lên.
B27: • | C27: Mỗi phản ánh một mã không trùng, ví dụ PA-012. Mã bị trùng sẽ tô đỏ.
B28: • | C28: Thời điểm ghi nhận nhập dạng dd/mm/yyyy hh:mm. Cách nhanh nhất: nhấn Ctrl+; để điền ngày hôm nay, gõ một dấu cách, rồi nhấn Ctrl+Shift+; để điền giờ hiện tại.
B29: • | C29: Kênh tiếp nhận (Zalo nhóm cư dân, hotline, trực tiếp, email, hộp thư góp ý, họp cư dân, BQL tự phát hiện) và Người phản ánh, căn hộ giúp liên hệ lại cư dân khi xử lý xong.
B30: • | C30: Người phụ trách là người chịu trách nhiệm chính và theo dõi đến khi xong; Người thực hiện trực tiếp là người bắt tay xử lý. Chọn trong danh sách (tab Danh mục, cột R và V) hoặc gõ tên khác; bảng Theo người phụ trách trên Tổng quan tự lấy tên từ dữ liệu. Gõ tên thống nhất để không bị tách thành hai người.
... B109: • | C109: Nên lưu một bản sao dự phòng mỗi tuần.
B111: Ban Quản trị Saigon South Residences

Sheet Tổng quan
F2: SAIGON SOUTH RESIDENCES | AH2: THỜI ĐIỂM BÁO CÁO
AH3: =NOW()
F4: =IF(SUM($AE$110:$AE$122)=0,IF($AR$8+$AS$8=0,"Chưa có việc nào quá hạn.","Không có việc nào quá hạn; "&TEXT($AR$8/($AR$8+$AS$8),"0%")&" việc xong trong 30 ngày qua là đúng hạn."),IF(MAX($AE$110:$AE$121)/SUM($AE$110:$AE$122)>=0.35,"Một người phụ trách đang giữ "&MAX($AE$110:$AE$121)&" trên "&SUM($AE$110:$AE$122)&" việc quá hạn, tức "&TEXT(MAX($AE$110:$AE$121)/SUM($AE$110:$AE$122),"0%")&IF(MAX($AE$110:$AE$121)/SUM($AE$110:$AE$122)>0.5,"; gỡ được chỗ nghẽn này là gỡ hơn một nửa số việc trễ.",IF(MAX($AE$110:$AE$121)/SUM($AE$110:$AE$122)>=0.45,", gần một nửa số việc trễ.",".")),IF($AR$8+$AS$8>0,"Trong 30 ngày qua, "&TEXT($AR$8/($AR$8+$AS$8),"0%")&" việc xong đúng hạn, nhưng "&SUM($AE$110:$AE$122)&" việc đang quá hạn.",SUM($AE$110:$AE$122)&" việc đang quá hạn.")))
F5: ="Bảng điều hành phản ánh cư dân và kế hoạch vận hành; số liệu tự cập nhật, tính đến "&TEXT(TDBC,"hh:mm")&" ngày "&TEXT(TDBC,"dd/mm/yyyy")&"."&IF('Lời nhắn'!$I$3>0," Có "&'Lời nhắn'!$I$3&" lời nhắn chưa phản hồi.","") | AH5: =CHOOSE(WEEKDAY(NgayBC),"Chủ nhật","Thứ Hai","Thứ Ba","Thứ Tư","Thứ Năm","Thứ Sáu","Thứ Bảy")
B7: =IF(AQ7+AR7+AS7+AT7=0,"KHÔNG CÓ VIỆC QUÁ HẠN. Mọi phản ánh và công việc đang trong hạn.","BÁO ĐỘNG: "&(AQ7+AR7+AS7+AT7)&" việc quá hạn, gồm "&LEFT(AU7,LEN(AU7)-2)&". Xem danh sách Cần chú ý; báo động tự tắt khi Nhật ký ghi hoàn thành.") | AH7: ="CHỈ SỐ "&AT8&"/100: "&IF(AT8>=85,"Tốt",IF(AT8>=70,"Ổn định",IF(AT8>=50,"Cần chú ý","Báo động"))) | AQ7: =COUNTIF('Phản ánh'!$AO$6:$AO$505,4)+COUNTIF('Kế hoạch'!$BB$6:$BB$305,4) | AR7: =COUNTIF('Phản ánh'!$AO$6:$AO$505,3)+COUNTIF('Kế hoạch'!$BB$6:$BB$305,3) | AS7: =COUNTIF('Phản ánh'!$AO$6:$AO$505,2)+COUNTIF('Kế hoạch'!$BB$6:$BB$305,2) | AT7: =COUNTIF('Phản ánh'!$AO$6:$AO$505,1)+COUNTIF('Kế hoạch'!$BB$6:$BB$305,1) | AU7: =IF(AQ7>0,AQ7&" báo động đỏ, ","")&IF(AR7>0,AR7&" báo động, ","")&IF(AS7>0,AS7&" cảnh báo, ","")&IF(AT7>0,AT7&" nhắc nhở, ","")
B8: PHẢN ÁNH CƯ DÂN | V8: KẾ HOẠCH VẬN HÀNH | AQ8: =COUNTIF('Phản ánh'!$Y$6:$Y$505,"Chậm tiến độ")+COUNTIF('Kế hoạch'!$AD$6:$AD$305,"Chậm tiến độ") | AR8: =COUNTIFS('Phản ánh'!$AE$6:$AE$505,"Đúng hạn",'Phản ánh'!$AA$6:$AA$505,">="&(TDBC-30))+COUNTIFS('Kế hoạch'!$AH$6:$AH$305,"Đúng hạn",'Kế hoạch'!$X$6:$X$305,">="&(TDBC-30))+COUNTIFS('Nhật ký tiến độ'!$E$6:$E$3005,"Hoàn thành kỳ",'Nhật ký tiến độ'!$M$6:$M$3005,"Đúng hạn",'Nhật ký tiến độ'!$B$6:$B$3005,">="&(TDBC-30)) | AS8: =COUNTIFS('Phản ánh'!$AE$6:$AE$505,"Trễ hạn",'Phản ánh'!$AA$6:$AA$505,">="&(TDBC-30))+COUNTIFS('Kế hoạch'!$AH$6:$AH$305,"Trễ hạn",'Kế hoạch'!$X$6:$X$305,">="&(TDBC-30))+COUNTIFS('Nhật ký tiến độ'!$E$6:$E$3005,"Hoàn thành kỳ",'Nhật ký tiến độ'!$M$6:$M$3005,"Trễ hạn",'Nhật ký tiến độ'!$B$6:$B$3005,">="&(TDBC-30)) | AT8: =MAX(0,ROUND(100-MIN(60,15*AQ7+10*AR7+5*AS7+2*AT7)-MIN(15,2*AQ8)-IF(AR8+AS8=0,0,MIN(25,(1-AR8/(AR8+AS8))*50)),0))
B10: TỒN ĐỌNG | G10: QUÁ HẠN | L10: CHẬM TIẾN ĐỘ | Q10: TIẾN ĐỘ BÌNH QUÂN | V10: ĐẾN HẠN HÔM NAY | AA10: TRONG 7 NGÀY TỚI | AF10: QUÁ HẠN | AK10: ĐÚNG HẠN 30 NGÀY
B11: =COUNTIFS('Phản ánh'!$A$6:$A$505,"?*",'Phản ánh'!$V$6:$V$505,"<>Đã xử lý") | G11: =COUNTIF('Phản ánh'!$Y$6:$Y$505,"Quá hạn") | L11: =COUNTIF('Phản ánh'!$Y$6:$Y$505,"Chậm tiến độ") | Q11: =IFERROR(AVERAGEIFS('Phản ánh'!$W$6:$W$505,'Phản ánh'!$A$6:$A$505,"?*",'Phản ánh'!$V$6:$V$505,"<>Đã xử lý"),0) | V11: =COUNTIFS('Kế hoạch'!$AO$6:$AO$305,1,'Kế hoạch'!$AP$6:$AP$305,NgayBC,'Kế hoạch'!$AR$6:$AR$305,0) | AA11: =COUNTIFS('Kế hoạch'!$AO$6:$AO$305,1,'Kế hoạch'!$AR$6:$AR$305,0,'Kế hoạch'!$AP$6:$AP$305,">="&NgayBC,'Kế hoạch'!$AP$6:$AP$305,"<="&(NgayBC+7)) | AF11: =COUNTIF('Kế hoạch'!$AD$6:$AD$305,"Quá hạn") | AK11: =IFERROR(COUNTIFS('Nhật ký tiến độ'!$I$6:$I$3005,"Công việc",'Nhật ký tiến độ'!$M$6:$M$3005,"Đúng hạn",'Nhật ký tiến độ'!$B$6:$B$3005,">="&(NgayBC-30),'Nhật ký tiến độ'!$B$6:$B$3005,"<="&TDBC)/(COUNTIFS('Nhật ký tiến độ'!$I$6:$I$3005,"Công việc",'Nhật ký tiến độ'!$M$6:$M$3005,"Đúng hạn",'Nhật ký tiến độ'!$B$6:$B$3005,">="&(NgayBC-30),'Nhật ký tiến độ'!$B$6:$B$3005,"<="&TDBC)+COUNTIFS('Nhật ký tiến độ'!$I$6:$I$3005,"Công việc",'Nhật ký tiến độ'!$M$6:$M$3005,"Trễ hạn",'Nhật ký tiến độ'!$B$6:$B$3005,">="&(NgayBC-30),'Nhật ký tiến độ'!$B$6:$B$3005,"<="&TDBC)),0)
B13: ="trên tổng "&COUNTIF('Phản ánh'!$A$6:$A$505,"?*")&" phản ánh" | G13: ="khẩn cấp chưa xong: "&COUNTIFS('Phản ánh'!$J$6:$J$505,"Khẩn cấp",'Phản ánh'!$V$6:$V$505,"<>Đã xử lý",'Phản ánh'!$A$6:$A$505,"?*") | L13: thấp hơn kế hoạch từ 20 điểm % | Q13: ="đã xử lý xong "&TEXT(IFERROR(COUNTIF('Phản ánh'!$V$6:$V$505,"Đã xử lý")/COUNTIF('Phản ánh'!$A$6:$A$505,"?*"),0),"0%")&" số phản ánh" | V13: ="cộng "&SUM('Kế hoạch'!$AR$6:$AR$305)&" việc hằng ngày" | AA13: việc định kỳ và đột xuất | AF13: ="đột xuất đang mở: "&COUNTIFS('Kế hoạch'!$B$6:$B$305,"Đột xuất",'Kế hoạch'!$AO$6:$AO$305,1) | AK13: =COUNTIFS('Nhật ký tiến độ'!$I$6:$I$3005,"Công việc",'Nhật ký tiến độ'!$M$6:$M$3005,"Đúng hạn",'Nhật ký tiến độ'!$B$6:$B$3005,">="&(NgayBC-30),'Nhật ký tiến độ'!$B$6:$B$3005,"<="&TDBC)&" trên "&(COUNTIFS('Nhật ký tiến độ'!$I$6:$I$3005,"Công việc",'Nhật ký tiến độ'!$M$6:$M$3005,"Đúng hạn",'Nhật ký tiến độ'!$B$6:$B$3005,">="&(NgayBC-30),'Nhật ký tiến độ'!$B$6:$B$3005,"<="&TDBC)+COUNTIFS('Nhật ký tiến độ'!$I$6:$I$3005,"Công việc",'Nhật ký tiến độ'!$M$6:$M$3005,"Trễ hạn",'Nhật ký tiến độ'!$B$6:$B$3005,">="&(NgayBC-30),'Nhật ký tiến độ'!$B$6:$B$3005,"<="&TDBC))&" lần hoàn thành công việc"
B15: ="Phản ánh cư dân: đang tồn đọng "&B11&" trên "&COUNTIF('Phản ánh'!$A$6:$A$505,"?*")&" phản ánh, tiến độ bình quân "&TEXT(Q11,"0%")&"; "&G11&" phản ánh quá hạn và "&L11&" phản ánh chậm tiến độ cần đôn đốc."
B16: ="Kế hoạch vận hành: "&V11&" việc đến hạn hôm nay, "&AA11&" việc trong 7 ngày tới, "&AF11&" việc quá hạn; tỷ lệ hoàn thành đúng hạn 30 ngày qua đạt "&TEXT(AK11,"0%")&"."
B18: LỊCH 14 NGÀY TỚI
B19: Chưa làm | E19: Hôm nay | G19: =CHOOSE(WEEKDAY(G20),"CN","T2","T3","T4","T5","T6","T7") | I19: =CHOOSE(WEEKDAY(I20),"CN","T2","T3","T4","T5","T6","T7") | K19: =CHOOSE(WEEKDAY(K20),"CN","T2","T3","T4","T5","T6","T7") | M19: =CHOOSE(WEEKDAY(M20),"CN","T2","T3","T4","T5","T6","T7") | O19: =CHOOSE(WEEKDAY(O20),"CN","T2","T3","T4","T5","T6","T7") | Q19: =CHOOSE(WEEKDAY(Q20),"CN","T2","T3","T4","T5","T6","T7") | S19: =CHOOSE(WEEKDAY(S20),"CN","T2","T3","T4","T5","T6","T7") | U19: =CHOOSE(WEEKDAY(U20),"CN","T2","T3","T4","T5","T6","T7") | W19: =CHOOSE(WEEKDAY(W20),"CN","T2","T3","T4","T5","T6","T7") | Y19: =CHOOSE(WEEKDAY(Y20),"CN","T2","T3","T4","T5","T6","T7") | AA19: =CHOOSE(WEEKDAY(AA20),"CN","T2","T3","T4","T5","T6","T7") | AC19: =CHOOSE(WEEKDAY(AC20),"CN","T2","T3","T4","T5","T6","T7") | AE19: =CHOOSE(WEEKDAY(AE20),"CN","T2","T3","T4","T5","T6","T7") | AH19: VIỆC HẰNG NGÀY
B20: Quá hạn | E20: =NgayBC+0 | G20: =NgayBC+1 | I20: =NgayBC+2 | K20: =NgayBC+3 | M20: =NgayBC+4 | O20: =NgayBC+5 | Q20: =NgayBC+6 | S20: =NgayBC+7 | U20: =NgayBC+8 | W20: =NgayBC+9 | Y20: =NgayBC+10 | AA20: =NgayBC+11 | AC20: =NgayBC+12 | AE20: =NgayBC+13 | AH20: =SUM('Kế hoạch'!$AR$6:$AR$305)&" việc"
B21: =COUNTIF('Kế hoạch'!$AD$6:$AD$305,"Quá hạn") | E21: =SUMPRODUCT(('Kế hoạch'!$AO$6:$AO$305=1)*('Kế hoạch'!$AQ$6:$AQ$305>0)*('Kế hoạch'!$AP$6:$AP$305>0)*(E$20>='Kế hoạch'!$AP$6:$AP$305)*(MOD(E$20-'Kế hoạch'!$AP$6:$AP$305,'Kế hoạch'!$AQ$6:$AQ$305+('Kế hoạch'!$AQ$6:$AQ$305=0))=0))+SUMPRODUCT(('Kế hoạch'!$AO$6:$AO$305=1)*('Kế hoạch'!$AQ$6:$AQ$305=0)*('Kế hoạch'!$AR$6:$AR$305=0)*('Kế hoạch'!$AP$6:$AP$305=E$20)) | G21: =SUMPRODUCT(('Kế hoạch'!$AO$6:$AO$305=1)*('Kế hoạch'!$AQ$6:$AQ$305>0)*('Kế hoạch'!$AP$6:$AP$305>0)*(G$20>='Kế hoạch'!$AP$6:$AP$305)*(MOD(G$20-'Kế hoạch'!$AP$6:$AP$305,'Kế hoạch'!$AQ$6:$AQ$305+('Kế hoạch'!$AQ$6:$AQ$305=0))=0))+SUMPRODUCT(('Kế hoạch'!$AO$6:$AO$305=1)*('Kế hoạch'!$AQ$6:$AQ$305=0)*('Kế hoạch'!$AR$6:$AR$305=0)*('Kế hoạch'!$AP$6:$AP$305=G$20)) | I21: =SUMPRODUCT(('Kế hoạch'!$AO$6:$AO$305=1)*('Kế hoạch'!$AQ$6:$AQ$305>0)*('Kế hoạch'!$AP$6:$AP$305>0)*(I$20>='Kế hoạch'!$AP$6:$AP$305)*(MOD(I$20-'Kế hoạch'!$AP$6:$AP$305,'Kế hoạch'!$AQ$6:$AQ$305+('Kế hoạch'!$AQ$6:$AQ$305=0))=0))+SUMPRODUCT(('Kế hoạch'!$AO$6:$AO$305=1)*('Kế hoạch'!$AQ$6:$AQ$305=0)*('Kế hoạch'!$AR$6:$AR$305=0)*('Kế hoạch'!$AP$6:$AP$305=I$20)) | K21: =SUMPRODUCT(('Kế hoạch'!$AO$6:$AO$305=1)*('Kế hoạch'!$AQ$6:$AQ$305>0)*('Kế hoạch'!$AP$6:$AP$305>0)*(K$20>='Kế hoạch'!$AP$6:$AP$305)*(MOD(K$20-'Kế hoạch'!$AP$6:$AP$305,'Kế hoạch'!$AQ$6:$AQ$305+('Kế hoạch'!$AQ$6:$AQ$305=0))=0))+SUMPRODUCT(('Kế hoạch'!$AO$6:$AO$305=1)*('Kế hoạch'!$AQ$6:$AQ$305=0)*('Kế hoạch'!$AR$6:$AR$305=0)*('Kế hoạch'!$AP$6:$AP$305=K$20)) | M21: =SUMPRODUCT(('Kế hoạch'!$AO$6:$AO$305=1)*('Kế hoạch'!$AQ$6:$AQ$305>0)*('Kế hoạch'!$AP$6:$AP$305>0)*(M$20>='Kế hoạch'!$AP$6:$AP$305)*(MOD(M$20-'Kế hoạch'!$AP$6:$AP$305,'Kế hoạch'!$AQ$6:$AQ$305+('Kế hoạch'!$AQ$6:$AQ$305=0))=0))+SUMPRODUCT(('Kế hoạch'!$AO$6:$AO$305=1)*('Kế hoạch'!$AQ$6:$AQ$305=0)*('Kế hoạch'!$AR$6:$AR$305=0)*('Kế hoạch'!$AP$6:$AP$305=M$20)) | O21: =SUMPRODUCT(('Kế hoạch'!$AO$6:$AO$305=1)*('Kế hoạch'!$AQ$6:$AQ$305>0)*('Kế hoạch'!$AP$6:$AP$305>0)*(O$20>='Kế hoạch'!$AP$6:$AP$305)*(MOD(O$20-'Kế hoạch'!$AP$6:$AP$305,'Kế hoạch'!$AQ$6:$AQ$305+('Kế hoạch'!$AQ$6:$AQ$305=0))=0))+SUMPRODUCT(('Kế hoạch'!$AO$6:$AO$305=1)*('Kế hoạch'!$AQ$6:$AQ$305=0)*('Kế hoạch'!$AR$6:$AR$305=0)*('Kế hoạch'!$AP$6:$AP$305=O$20)) | Q21: =SUMPRODUCT(('Kế hoạch'!$AO$6:$AO$305=1)*('Kế hoạch'!$AQ$6:$AQ$305>0)*('Kế hoạch'!$AP$6:$AP$305>0)*(Q$20>='Kế hoạch'!$AP$6:$AP$305)*(MOD(Q$20-'Kế hoạch'!$AP$6:$AP$305,'Kế hoạch'!$AQ$6:$AQ$305+('Kế hoạch'!$AQ$6:$AQ$305=0))=0))+SUMPRODUCT(('Kế hoạch'!$AO$6:$AO$305=1)*('Kế hoạch'!$AQ$6:$AQ$305=0)*('Kế hoạch'!$AR$6:$AR$305=0)*('Kế hoạch'!$AP$6:$AP$305=Q$20)) | S21: =SUMPRODUCT(('Kế hoạch'!$AO$6:$AO$305=1)*('Kế hoạch'!$AQ$6:$AQ$305>0)*('Kế hoạch'!$AP$6:$AP$305>0)*(S$20>='Kế hoạch'!$AP$6:$AP$305)*(MOD(S$20-'Kế hoạch'!$AP$6:$AP$305,'Kế hoạch'!$AQ$6:$AQ$305+('Kế hoạch'!$AQ$6:$AQ$305=0))=0))+SUMPRODUCT(('Kế hoạch'!$AO$6:$AO$305=1)*('Kế hoạch'!$AQ$6:$AQ$305=0)*('Kế hoạch'!$AR$6:$AR$305=0)*('Kế hoạch'!$AP$6:$AP$305=S$20)) | U21: =SUMPRODUCT(('Kế hoạch'!$AO$6:$AO$305=1)*('Kế hoạch'!$AQ$6:$AQ$305>0)*('Kế hoạch'!$AP$6:$AP$305>0)*(U$20>='Kế hoạch'!$AP$6:$AP$305)*(MOD(U$20-'Kế hoạch'!$AP$6:$AP$305,'Kế hoạch'!$AQ$6:$AQ$305+('Kế hoạch'!$AQ$6:$AQ$305=0))=0))+SUMPRODUCT(('Kế hoạch'!$AO$6:$AO$305=1)*('Kế hoạch'!$AQ$6:$AQ$305=0)*('Kế hoạch'!$AR$6:$AR$305=0)*('Kế hoạch'!$AP$6:$AP$305=U$20)) | W21: =SUMPRODUCT(('Kế hoạch'!$AO$6:$AO$305=1)*('Kế hoạch'!$AQ$6:$AQ$305>0)*('Kế hoạch'!$AP$6:$AP$305>0)*(W$20>='Kế hoạch'!$AP$6:$AP$305)*(MOD(W$20-'Kế hoạch'!$AP$6:$AP$305,'Kế hoạch'!$AQ$6:$AQ$305+('Kế hoạch'!$AQ$6:$AQ$305=0))=0))+SUMPRODUCT(('Kế hoạch'!$AO$6:$AO$305=1)*('Kế hoạch'!$AQ$6:$AQ$305=0)*('Kế hoạch'!$AR$6:$AR$305=0)*('Kế hoạch'!$AP$6:$AP$305=W$20)) | Y21: =SUMPRODUCT(('Kế hoạch'!$AO$6:$AO$305=1)*('Kế hoạch'!$AQ$6:$AQ$305>0)*('Kế hoạch'!$AP$6:$AP$305>0)*(Y$20>='Kế hoạch'!$AP$6:$AP$305)*(MOD(Y$20-'Kế hoạch'!$AP$6:$AP$305,'Kế hoạch'!$AQ$6:$AQ$305+('Kế hoạch'!$AQ$6:$AQ$305=0))=0))+SUMPRODUCT(('Kế hoạch'!$AO$6:$AO$305=1)*('Kế hoạch'!$AQ$6:$AQ$305=0)*('Kế hoạch'!$AR$6:$AR$305=0)*('Kế hoạch'!$AP$6:$AP$305=Y$20)) | AA21: =SUMPRODUCT(('Kế hoạch'!$AO$6:$AO$305=1)*('Kế hoạch'!$AQ$6:$AQ$305>0)*('Kế hoạch'!$AP$6:$AP$305>0)*(AA$20>='Kế hoạch'!$AP$6:$AP$305)*(MOD(AA$20-'Kế hoạch'!$AP$6:$AP$305,'Kế hoạch'!$AQ$6:$AQ$305+('Kế hoạch'!$AQ$6:$AQ$305=0))=0))+SUMPRODUCT(('Kế hoạch'!$AO$6:$AO$305=1)*('Kế hoạch'!$AQ$6:$AQ$305=0)*('Kế hoạch'!$AR$6:$AR$305=0)*('Kế hoạch'!$AP$6:$AP$305=AA$20)) | AC21: =SUMPRODUCT(('Kế hoạch'!$AO$6:$AO$305=1)*('Kế hoạch'!$AQ$6:$AQ$305>0)*('Kế hoạch'!$AP$6:$AP$305>0)*(AC$20>='Kế hoạch'!$AP$6:$AP$305)*(MOD(AC$20-'Kế hoạch'!$AP$6:$AP$305,'Kế hoạch'!$AQ$6:$AQ$305+('Kế hoạch'!$AQ$6:$AQ$305=0))=0))+SUMPRODUCT(('Kế hoạch'!$AO$6:$AO$305=1)*('Kế hoạch'!$AQ$6:$AQ$305=0)*('Kế hoạch'!$AR$6:$AR$305=0)*('Kế hoạch'!$AP$6:$AP$305=AC$20)) | AE21: =SUMPRODUCT(('Kế hoạch'!$AO$6:$AO$305=1)*('Kế hoạch'!$AQ$6:$AQ$305>0)*('Kế hoạch'!$AP$6:$AP$305>0)*(AE$20>='Kế hoạch'!$AP$6:$AP$305)*(MOD(AE$20-'Kế hoạch'!$AP$6:$AP$305,'Kế hoạch'!$AQ$6:$AQ$305+('Kế hoạch'!$AQ$6:$AQ$305=0))=0))+SUMPRODUCT(('Kế hoạch'!$AO$6:$AO$305=1)*('Kế hoạch'!$AQ$6:$AQ$305=0)*('Kế hoạch'!$AR$6:$AR$305=0)*('Kế hoạch'!$AP$6:$AP$305=AE$20)) | AH21: lặp lại mỗi ngày, không tính vào các ô ngày
B23: BIỂU ĐỒ PHÂN TÍCH
B60: SƠ ĐỒ KHU VỰC | AB60: THEO KHU VỰC
B61: Mỗi tháp là một block 23 tầng. Ô đỏ: phản ánh khẩn cấp hoặc mức cao; ô cam: mức trung bình hoặc thấp; con số là số phản ánh đang mở. Ô vàng ghi CV: tầng có công việc đang triển khai. | AB61: Phản ánh đang mở, công việc chưa xong (không tính việc hằng ngày) và số đầu việc quá hạn. Cần xử lý: có đầu việc quá hạn; Theo dõi: đang có việc mở.
B62: Mái | D62: =IF(COUNTIFS('Phản ánh'!$F$6:$F$505,"Block A",'Phản ánh'!$G$6:$G$505,$B62,'Phản ánh'!$V$6:$V$505,"<>Đã xử lý")>0,IF((COUNTIFS('Phản ánh'!$F$6:$F$505,"Block A",'Phản ánh'!$G$6:$G$505,$B62,'Phản ánh'!$V$6:$V$505,"<>Đã xử lý",'Phản ánh'!$J$6:$J$505,"Khẩn cấp")+COUNTIFS('Phản ánh'!$F$6:$F$505,"Block A",'Phản ánh'!$G$6:$G$505,$B62,'Phản ánh'!$V$6:$V$505,"<>Đã xử lý",'Phản ánh'!$J$6:$J$505,"Cao"))>0,-COUNTIFS('Phản ánh'!$F$6:$F$505,"Block A",'Phản ánh'!$G$6:$G$505,$B62,'Phản ánh'!$V$6:$V$505,"<>Đã xử lý"),COUNTIFS('Phản ánh'!$F$6:$F$505,"Block A",'Phản ánh'!$G$6:$G$505,$B62,'Phản ánh'!$V$6:$V$505,"<>Đã xử lý")),IF(COUNTIFS('Kế hoạch'!$E$6:$E$305,"Block A",'Kế hoạch'!$F$6:$F$305,$B62,'Kế hoạch'!$AO$6:$AO$305,1)>0,"CV","")) | H62: =IF(COUNTIFS('Phản ánh'!$F$6:$F$505,"Block B",'Phản ánh'!$G$6:$G$505,$B62,'Phản ánh'!$V$6:$V$505,"<>Đã xử lý")>0,IF((COUNTIFS('Phản ánh'!$F$6:$F$505,"Block B",'Phản ánh'!$G$6:$G$505,$B62,'Phản ánh'!$V$6:$V$505,"<>Đã xử lý",'Phản ánh'!$J$6:$J$505,"Khẩn cấp")+COUNTIFS('Phản ánh'!$F$6:$F$505,"Block B",'Phản ánh'!$G$6:$G$505,$B62,'Phản ánh'!$V$6:$V$505,"<>Đã xử lý",'Phản ánh'!$J$6:$J$505,"Cao"))>0,-COUNTIFS('Phản ánh'!$F$6:$F$505,"Block B",'Phản ánh'!$G$6:$G$505,$B62,'Phản ánh'!$V$6:$V$505,"<>Đã xử lý"),COUNTIFS('Phản ánh'!$F$6:$F$505,"Block B",'Phản ánh'!$G$6:$G$505,$B62,'Phản ánh'!$V$6:$V$505,"<>Đã xử lý")),IF(COUNTIFS('Kế hoạch'!$E$6:$E$305,"Block B",'Kế hoạch'!$F$6:$F$305,$B62,'Kế hoạch'!$AO$6:$AO$305,1)>0,"CV","")) | L62: =IF(COUNTIFS('Phản ánh'!$F$6:$F$505,"Block C",'Phản ánh'!$G$6:$G$505,$B62,'Phản ánh'!$V$6:$V$505,"<>Đã xử lý")>0,IF((COUNTIFS('Phản ánh'!$F$6:$F$505,"Block C",'Phản ánh'!$G$6:$G$505,$B62,'Phản ánh'!$V$6:$V$505,"<>Đã xử lý",'Phản ánh'!$J$6:$J$505,"Khẩn cấp")+COUNTIFS('Phản ánh'!$F$6:$F$505,"Block C",'Phản ánh'!$G$6:$G$505,$B62,'Phản ánh'!$V$6:$V$505,"<>Đã xử lý",'Phản ánh'!$J$6:$J$505,"Cao"))>0,-COUNTIFS('Phản ánh'!$F$6:$F$505,"Block C",'Phản ánh'!$G$6:$G$505,$B62,'Phản ánh'!$V$6:$V$505,"<>Đã xử lý"),COUNTIFS('Phản ánh'!$F$6:$F$505,"Block C",'Phản ánh'!$G$6:$G$505,$B62,'Phản ánh'!$V$6:$V$505,"<>Đã xử lý")),IF(COUNTIFS('Kế hoạch'!$E$6:$E$305,"Block C",'Kế hoạch'!$F$6:$F$305,$B62,'Kế hoạch'!$AO$6:$AO$305,1)>0,"CV","")) | P62: =IF(COUNTIFS('Phản ánh'!$F$6:$F$505,"Block D",'Phản ánh'!$G$6:$G$505,$B62,'Phản ánh'!$V$6:$V$505,"<>Đã xử lý")>0,IF((COUNTIFS('Phản ánh'!$F$6:$F$505,"Block D",'Phản ánh'!$G$6:$G$505,$B62,'Phản ánh'!$V$6:$V$505,"<>Đã xử lý",'Phản ánh'!$J$6:$J$505,"Khẩn cấp")+COUNTIFS('Phản ánh'!$F$6:$F$505,"Block D",'Phản ánh'!$G$6:$G$505,$B62,'Phản ánh'!$V$6:$V$505,"<>Đã xử lý",'Phản ánh'!$J$6:$J$505,"Cao"))>0,-COUNTIFS('Phản ánh'!$F$6:$F$505,"Block D",'Phản ánh'!$G$6:$G$505,$B62,'Phản ánh'!$V$6:$V$505,"<>Đã xử lý"),COUNTIFS('Phản ánh'!$F$6:$F$505,"Block D",'Phản ánh'!$G$6:$G$505,$B62,'Phản ánh'!$V$6:$V$505,"<>Đã xử lý")),IF(COUNTIFS('Kế hoạch'!$E$6:$E$305,"Block D",'Kế hoạch'!$F$6:$F$305,$B62,'Kế hoạch'!$AO$6:$AO$305,1)>0,"CV","")) | T62: =IF(COUNTIFS('Phản ánh'!$F$6:$F$505,"Block E",'Phản ánh'!$G$6:$G$505,$B62,'Phản ánh'!$V$6:$V$505,"<>Đã xử lý")>0,IF((COUNTIFS('Phản ánh'!$F$6:$F$505,"Block E",'Phản ánh'!$G$6:$G$505,$B62,'Phản ánh'!$V$6:$V$505,"<>Đã xử lý",'Phản ánh'!$J$6:$J$505,"Khẩn cấp")+COUNTIFS('Phản ánh'!$F$6:$F$505,"Block E",'Phản ánh'!$G$6:$G$505,$B62,'Phản ánh'!$V$6:$V$505,"<>Đã xử lý",'Phản ánh'!$J$6:$J$505,"Cao"))>0,-COUNTIFS('Phản ánh'!$F$6:$F$505,"Block E",'Phản ánh'!$G$6:$G$505,$B62,'Phản ánh'!$V$6:$V$505,"<>Đã xử lý"),COUNTIFS('Phản ánh'!$F$6:$F$505,"Block E",'Phản ánh'!$G$6:$G$505,$B62,'Phản ánh'!$V$6:$V$505,"<>Đã xử lý")),IF(COUNTIFS('Kế hoạch'!$E$6:$E$305,"Block E",'Kế hoạch'!$F$6:$F$305,$B62,'Kế hoạch'!$AO$6:$AO$305,1)>0,"CV","")) | X62: =IF(COUNTIFS('Phản ánh'!$F$6:$F$505,"Block G",'Phản ánh'!$G$6:$G$505,$B62,'Phản ánh'!$V$6:$V$505,"<>Đã xử lý")>0,IF((COUNTIFS('Phản ánh'!$F$6:$F$505,"Block G",'Phản ánh'!$G$6:$G$505,$B62,'Phản ánh'!$V$6:$V$505,"<>Đã xử lý",'Phản ánh'!$J$6:$J$505,"Khẩn cấp")+COUNTIFS('Phản ánh'!$F$6:$F$505,"Block G",'Phản ánh'!$G$6:$G$505,$B62,'Phản ánh'!$V$6:$V$505,"<>Đã xử lý",'Phản ánh'!$J$6:$J$505,"Cao"))>0,-COUNTIFS('Phản ánh'!$F$6:$F$505,"Block G",'Phản ánh'!$G$6:$G$505,$B62,'Phản ánh'!$V$6:$V$505,"<>Đã xử lý"),COUNTIFS('Phản ánh'!$F$6:$F$505,"Block G",'Phản ánh'!$G$6:$G$505,$B62,'Phản ánh'!$V$6:$V$505,"<>Đã xử lý")),IF(COUNTIFS('Kế hoạch'!$E$6:$E$305,"Block G",'Kế hoạch'!$F$6:$F$305,$B62,'Kế hoạch'!$AO$6:$AO$305,1)>0,"CV","")) | AB62: Khu vực | AG62: Phản ánh | AI62: Việc | AK62: Quá hạn | AM62: Tình trạng
B63: 23 | D63: =IF(COUNTIFS('Phản ánh'!$F$6:$F$505,"Block A",'Phản ánh'!$G$6:$G$505,$B63,'Phản ánh'!$V$6:$V$505,"<>Đã xử lý")>0,IF((COUNTIFS('Phản ánh'!$F$6:$F$505,"Block A",'Phản ánh'!$G$6:$G$505,$B63,'Phản ánh'!$V$6:$V$505,"<>Đã xử lý",'Phản ánh'!$J$6:$J$505,"Khẩn cấp")+COUNTIFS('Phản ánh'!$F$6:$F$505,"Block A",'Phản ánh'!$G$6:$G$505,$B63,'Phản ánh'!$V$6:$V$505,"<>Đã xử lý",'Phản ánh'!$J$6:$J$505,"Cao"))>0,-COUNTIFS('Phản ánh'!$F$6:$F$505,"Block A",'Phản ánh'!$G$6:$G$505,$B63,'Phản ánh'!$V$6:$V$505,"<>Đã xử lý"),COUNTIFS('Phản ánh'!$F$6:$F$505,"Block A",'Phản ánh'!$G$6:$G$505,$B63,'Phản ánh'!$V$6:$V$505,"<>Đã xử lý")),IF(COUNTIFS('Kế hoạch'!$E$6:$E$305,"Block A",'Kế hoạch'!$F$6:$F$305,$B63,'Kế hoạch'!$AO$6:$AO$305,1)>0,"CV","")) | H63: =IF(COUNTIFS('Phản ánh'!$F$6:$F$505,"Block B",'Phản ánh'!$G$6:$G$505,$B63,'Phản ánh'!$V$6:$V$505,"<>Đã xử lý")>0,IF((COUNTIFS('Phản ánh'!$F$6:$F$505,"Block B",'Phản ánh'!$G$6:$G$505,$B63,'Phản ánh'!$V$6:$V$505,"<>Đã xử lý",'Phản ánh'!$J$6:$J$505,"Khẩn cấp")+COUNTIFS('Phản ánh'!$F$6:$F$505,"Block B",'Phản ánh'!$G$6:$G$505,$B63,'Phản ánh'!$V$6:$V$505,"<>Đã xử lý",'Phản ánh'!$J$6:$J$505,"Cao"))>0,-COUNTIFS('Phản ánh'!$F$6:$F$505,"Block B",'Phản ánh'!$G$6:$G$505,$B63,'Phản ánh'!$V$6:$V$505,"<>Đã xử lý"),COUNTIFS('Phản ánh'!$F$6:$F$505,"Block B",'Phản ánh'!$G$6:$G$505,$B63,'Phản ánh'!$V$6:$V$505,"<>Đã xử lý")),IF(COUNTIFS('Kế hoạch'!$E$6:$E$305,"Block B",'Kế hoạch'!$F$6:$F$305,$B63,'Kế hoạch'!$AO$6:$AO$305,1)>0,"CV","")) | L63: =IF(COUNTIFS('Phản ánh'!$F$6:$F$505,"Block C",'Phản ánh'!$G$6:$G$505,$B63,'Phản ánh'!$V$6:$V$505,"<>Đã xử lý")>0,IF((COUNTIFS('Phản ánh'!$F$6:$F$505,"Block C",'Phản ánh'!$G$6:$G$505,$B63,'Phản ánh'!$V$6:$V$505,"<>Đã xử lý",'Phản ánh'!$J$6:$J$505,"Khẩn cấp")+COUNTIFS('Phản ánh'!$F$6:$F$505,"Block C",'Phản ánh'!$G$6:$G$505,$B63,'Phản ánh'!$V$6:$V$505,"<>Đã xử lý",'Phản ánh'!$J$6:$J$505,"Cao"))>0,-COUNTIFS('Phản ánh'!$F$6:$F$505,"Block C",'Phản ánh'!$G$6:$G$505,$B63,'Phản ánh'!$V$6:$V$505,"<>Đã xử lý"),COUNTIFS('Phản ánh'!$F$6:$F$505,"Block C",'Phản ánh'!$G$6:$G$505,$B63,'Phản ánh'!$V$6:$V$505,"<>Đã xử lý")),IF(COUNTIFS('Kế hoạch'!$E$6:$E$305,"Block C",'Kế hoạch'!$F$6:$F$305,$B63,'Kế hoạch'!$AO$6:$AO$305,1)>0,"CV","")) | P63: =IF(COUNTIFS('Phản ánh'!$F$6:$F$505,"Block D",'Phản ánh'!$G$6:$G$505,$B63,'Phản ánh'!$V$6:$V$505,"<>Đã xử lý")>0,IF((COUNTIFS('Phản ánh'!$F$6:$F$505,"Block D",'Phản ánh'!$G$6:$G$505,$B63,'Phản ánh'!$V$6:$V$505,"<>Đã xử lý",'Phản ánh'!$J$6:$J$505,"Khẩn cấp")+COUNTIFS('Phản ánh'!$F$6:$F$505,"Block D",'Phản ánh'!$G$6:$G$505,$B63,'Phản ánh'!$V$6:$V$505,"<>Đã xử lý",'Phản ánh'!$J$6:$J$505,"Cao"))>0,-COUNTIFS('Phản ánh'!$F$6:$F$505,"Block D",'Phản ánh'!$G$6:$G$505,$B63,'Phản ánh'!$V$6:$V$505,"<>Đã xử lý"),COUNTIFS('Phản ánh'!$F$6:$F$505,"Block D",'Phản ánh'!$G$6:$G$505,$B63,'Phản ánh'!$V$6:$V$505,"<>Đã xử lý")),IF(COUNTIFS('Kế hoạch'!$E$6:$E$305,"Block D",'Kế hoạch'!$F$6:$F$305,$B63,'Kế hoạch'!$AO$6:$AO$305,1)>0,"CV","")) | T63: =IF(COUNTIFS('Phản ánh'!$F$6:$F$505,"Block E",'Phản ánh'!$G$6:$G$505,$B63,'Phản ánh'!$V$6:$V$505,"<>Đã xử lý")>0,IF((COUNTIFS('Phản ánh'!$F$6:$F$505,"Block E",'Phản ánh'!$G$6:$G$505,$B63,'Phản ánh'!$V$6:$V$505,"<>Đã xử lý",'Phản ánh'!$J$6:$J$505,"Khẩn cấp")+COUNTIFS('Phản ánh'!$F$6:$F$505,"Block E",'Phản ánh'!$G$6:$G$505,$B63,'Phản ánh'!$V$6:$V$505,"<>Đã xử lý",'Phản ánh'!$J$6:$J$505,"Cao"))>0,-COUNTIFS('Phản ánh'!$F$6:$F$505,"Block E",'Phản ánh'!$G$6:$G$505,$B63,'Phản ánh'!$V$6:$V$505,"<>Đã xử lý"),COUNTIFS('Phản ánh'!$F$6:$F$505,"Block E",'Phản ánh'!$G$6:$G$505,$B63,'Phản ánh'!$V$6:$V$505,"<>Đã xử lý")),IF(COUNTIFS('Kế hoạch'!$E$6:$E$305,"Block E",'Kế hoạch'!$F$6:$F$305,$B63,'Kế hoạch'!$AO$6:$AO$305,1)>0,"CV","")) | X63: =IF(COUNTIFS('Phản ánh'!$F$6:$F$505,"Block G",'Phản ánh'!$G$6:$G$505,$B63,'Phản ánh'!$V$6:$V$505,"<>Đã xử lý")>0,IF((COUNTIFS('Phản ánh'!$F$6:$F$505,"Block G",'Phản ánh'!$G$6:$G$505,$B63,'Phản ánh'!$V$6:$V$505,"<>Đã xử lý",'Phản ánh'!$J$6:$J$505,"Khẩn cấp")+COUNTIFS('Phản ánh'!$F$6:$F$505,"Block G",'Phản ánh'!$G$6:$G$505,$B63,'Phản ánh'!$V$6:$V$505,"<>Đã xử lý",'Phản ánh'!$J$6:$J$505,"Cao"))>0,-COUNTIFS('Phản ánh'!$F$6:$F$505,"Block G",'Phản ánh'!$G$6:$G$505,$B63,'Phản ánh'!$V$6:$V$505,"<>Đã xử lý"),COUNTIFS('Phản ánh'!$F$6:$F$505,"Block G",'Phản ánh'!$G$6:$G$505,$B63,'Phản ánh'!$V$6:$V$505,"<>Đã xử lý")),IF(COUNTIFS('Kế hoạch'!$E$6:$E$305,"Block G",'Kế hoạch'!$F$6:$F$305,$B63,'Kế hoạch'!$AO$6:$AO$305,1)>0,"CV","")) | AB63: Block A | AG63: =COUNTIFS('Phản ánh'!$F$6:$F$505,$AB63,'Phản ánh'!$V$6:$V$505,"<>Đã xử lý") | AI63: =COUNTIFS('Kế hoạch'!$E$6:$E$305,$AB63,'Kế hoạch'!$AO$6:$AO$305,1,'Kế hoạch'!$AR$6:$AR$305,0) | AK63: =COUNTIFS('Phản ánh'!$F$6:$F$505,$AB63,'Phản ánh'!$Y$6:$Y$505,"Quá hạn")+COUNTIFS('Kế hoạch'!$E$6:$E$305,$AB63,'Kế hoạch'!$AD$6:$AD$305,"Quá hạn") | AM63: =IF(AK63>0,"Cần xử lý",IF(AG63+AI63>0,"Theo dõi","Ổn định"))
B64: 22 | D64: =IF(COUNTIFS('Phản ánh'!$F$6:$F$505,"Block A",'Phản ánh'!$G$6:$G$505,$B64,'Phản ánh'!$V$6:$V$505,"<>Đã xử lý")>0,IF((COUNTIFS('Phản ánh'!$F$6:$F$505,"Block A",'Phản ánh'!$G$6:$G$505,$B64,'Phản ánh'!$V$6:$V$505,"<>Đã xử lý",'Phản ánh'!$J$6:$J$505,"Khẩn cấp")+COUNTIFS('Phản ánh'!$F$6:$F$505,"Block A",'Phản ánh'!$G$6:$G$505,$B64,'Phản ánh'!$V$6:$V$505,"<>Đã xử lý",'Phản ánh'!$J$6:$J$505,"Cao"))>0,-COUNTIFS('Phản ánh'!$F$6:$F$505,"Block A",'Phản ánh'!$G$6:$G$505,$B64,'Phản ánh'!$V$6:$V$505,"<>Đã xử lý"),COUNTIFS('Phản ánh'!$F$6:$F$505,"Block A",'Phản ánh'!$G$6:$G$505,$B64,'Phản ánh'!$V$6:$V$505,"<>Đã xử lý")),IF(COUNTIFS('Kế hoạch'!$E$6:$E$305,"Block A",'Kế hoạch'!$F$6:$F$305,$B64,'Kế hoạch'!$AO$6:$AO$305,1)>0,"CV","")) | H64: =IF(COUNTIFS('Phản ánh'!$F$6:$F$505,"Block B",'Phản ánh'!$G$6:$G$505,$B64,'Phản ánh'!$V$6:$V$505,"<>Đã xử lý")>0,IF((COUNTIFS('Phản ánh'!$F$6:$F$505,"Block B",'Phản ánh'!$G$6:$G$505,$B64,'Phản ánh'!$V$6:$V$505,"<>Đã xử lý",'Phản ánh'!$J$6:$J$505,"Khẩn cấp")+COUNTIFS('Phản ánh'!$F$6:$F$505,"Block B",'Phản ánh'!$G$6:$G$505,$B64,'Phản ánh'!$V$6:$V$505,"<>Đã xử lý",'Phản ánh'!$J$6:$J$505,"Cao"))>0,-COUNTIFS('Phản ánh'!$F$6:$F$505,"Block B",'Phản ánh'!$G$6:$G$505,$B64,'Phản ánh'!$V$6:$V$505,"<>Đã xử lý"),COUNTIFS('Phản ánh'!$F$6:$F$505,"Block B",'Phản ánh'!$G$6:$G$505,$B64,'Phản ánh'!$V$6:$V$505,"<>Đã xử lý")),IF(COUNTIFS('Kế hoạch'!$E$6:$E$305,"Block B",'Kế hoạch'!$F$6:$F$305,$B64,'Kế hoạch'!$AO$6:$AO$305,1)>0,"CV","")) | L64: =IF(COUNTIFS('Phản ánh'!$F$6:$F$505,"Block C",'Phản ánh'!$G$6:$G$505,$B64,'Phản ánh'!$V$6:$V$505,"<>Đã xử lý")>0,IF((COUNTIFS('Phản ánh'!$F$6:$F$505,"Block C",'Phản ánh'!$G$6:$G$505,$B64,'Phản ánh'!$V$6:$V$505,"<>Đã xử lý",'Phản ánh'!$J$6:$J$505,"Khẩn cấp")+COUNTIFS('Phản ánh'!$F$6:$F$505,"Block C",'Phản ánh'!$G$6:$G$505,$B64,'Phản ánh'!$V$6:$V$505,"<>Đã xử lý",'Phản ánh'!$J$6:$J$505,"Cao"))>0,-COUNTIFS('Phản ánh'!$F$6:$F$505,"Block C",'Phản ánh'!$G$6:$G$505,$B64,'Phản ánh'!$V$6:$V$505,"<>Đã xử lý"),COUNTIFS('Phản ánh'!$F$6:$F$505,"Block C",'Phản ánh'!$G$6:$G$505,$B64,'Phản ánh'!$V$6:$V$505,"<>Đã xử lý")),IF(COUNTIFS('Kế hoạch'!$E$6:$E$305,"Block C",'Kế hoạch'!$F$6:$F$305,$B64,'Kế hoạch'!$AO$6:$AO$305,1)>0,"CV","")) | P64: =IF(COUNTIFS('Phản ánh'!$F$6:$F$505,"Block D",'Phản ánh'!$G$6:$G$505,$B64,'Phản ánh'!$V$6:$V$505,"<>Đã xử lý")>0,IF((COUNTIFS('Phản ánh'!$F$6:$F$505,"Block D",'Phản ánh'!$G$6:$G$505,$B64,'Phản ánh'!$V$6:$V$505,"<>Đã xử lý",'Phản ánh'!$J$6:$J$505,"Khẩn cấp")+COUNTIFS('Phản ánh'!$F$6:$F$505,"Block D",'Phản ánh'!$G$6:$G$505,$B64,'Phản ánh'!$V$6:$V$505,"<>Đã xử lý",'Phản ánh'!$J$6:$J$505,"Cao"))>0,-COUNTIFS('Phản ánh'!$F$6:$F$505,"Block D",'Phản ánh'!$G$6:$G$505,$B64,'Phản ánh'!$V$6:$V$505,"<>Đã xử lý"),COUNTIFS('Phản ánh'!$F$6:$F$505,"Block D",'Phản ánh'!$G$6:$G$505,$B64,'Phản ánh'!$V$6:$V$505,"<>Đã xử lý")),IF(COUNTIFS('Kế hoạch'!$E$6:$E$305,"Block D",'Kế hoạch'!$F$6:$F$305,$B64,'Kế hoạch'!$AO$6:$AO$305,1)>0,"CV","")) | T64: =IF(COUNTIFS('Phản ánh'!$F$6:$F$505,"Block E",'Phản ánh'!$G$6:$G$505,$B64,'Phản ánh'!$V$6:$V$505,"<>Đã xử lý")>0,IF((COUNTIFS('Phản ánh'!$F$6:$F$505,"Block E",'Phản ánh'!$G$6:$G$505,$B64,'Phản ánh'!$V$6:$V$505,"<>Đã xử lý",'Phản ánh'!$J$6:$J$505,"Khẩn cấp")+COUNTIFS('Phản ánh'!$F$6:$F$505,"Block E",'Phản ánh'!$G$6:$G$505,$B64,'Phản ánh'!$V$6:$V$505,"<>Đã xử lý",'Phản ánh'!$J$6:$J$505,"Cao"))>0,-COUNTIFS('Phản ánh'!$F$6:$F$505,"Block E",'Phản ánh'!$G$6:$G$505,$B64,'Phản ánh'!$V$6:$V$505,"<>Đã xử lý"),COUNTIFS('Phản ánh'!$F$6:$F$505,"Block E",'Phản ánh'!$G$6:$G$505,$B64,'Phản ánh'!$V$6:$V$505,"<>Đã xử lý")),IF(COUNTIFS('Kế hoạch'!$E$6:$E$305,"Block E",'Kế hoạch'!$F$6:$F$305,$B64,'Kế hoạch'!$AO$6:$AO$305,1)>0,"CV","")) | X64: =IF(COUNTIFS('Phản ánh'!$F$6:$F$505,"Block G",'Phản ánh'!$G$6:$G$505,$B64,'Phản ánh'!$V$6:$V$505,"<>Đã xử lý")>0,IF((COUNTIFS('Phản ánh'!$F$6:$F$505,"Block G",'Phản ánh'!$G$6:$G$505,$B64,'Phản ánh'!$V$6:$V$505,"<>Đã xử lý",'Phản ánh'!$J$6:$J$505,"Khẩn cấp")+COUNTIFS('Phản ánh'!$F$6:$F$505,"Block G",'Phản ánh'!$G$6:$G$505,$B64,'Phản ánh'!$V$6:$V$505,"<>Đã xử lý",'Phản ánh'!$J$6:$J$505,"Cao"))>0,-COUNTIFS('Phản ánh'!$F$6:$F$505,"Block G",'Phản ánh'!$G$6:$G$505,$B64,'Phản ánh'!$V$6:$V$505,"<>Đã xử lý"),COUNTIFS('Phản ánh'!$F$6:$F$505,"Block G",'Phản ánh'!$G$6:$G$505,$B64,'Phản ánh'!$V$6:$V$505,"<>Đã xử lý")),IF(COUNTIFS('Kế hoạch'!$E$6:$E$305,"Block G",'Kế hoạch'!$F$6:$F$305,$B64,'Kế hoạch'!$AO$6:$AO$305,1)>0,"CV","")) | AB64: Block B | AG64: =COUNTIFS('Phản ánh'!$F$6:$F$505,$AB64,'Phản ánh'!$V$6:$V$505,"<>Đã xử lý") | AI64: =COUNTIFS('Kế hoạch'!$E$6:$E$305,$AB64,'Kế hoạch'!$AO$6:$AO$305,1,'Kế hoạch'!$AR$6:$AR$305,0) | AK64: =COUNTIFS('Phản ánh'!$F$6:$F$505,$AB64,'Phản ánh'!$Y$6:$Y$505,"Quá hạn")+COUNTIFS('Kế hoạch'!$E$6:$E$305,$AB64,'Kế hoạch'!$AD$6:$AD$305,"Quá hạn") | AM64: =IF(AK64>0,"Cần xử lý",IF(AG64+AI64>0,"Theo dõi","Ổn định"))
B65: 21 | D65: =IF(COUNTIFS('Phản ánh'!$F$6:$F$505,"Block A",'Phản ánh'!$G$6:$G$505,$B65,'Phản ánh'!$V$6:$V$505,"<>Đã xử lý")>0,IF((COUNTIFS('Phản ánh'!$F$6:$F$505,"Block A",'Phản ánh'!$G$6:$G$505,$B65,'Phản ánh'!$V$6:$V$505,"<>Đã xử lý",'Phản ánh'!$J$6:$J$505,"Khẩn cấp")+COUNTIFS('Phản ánh'!$F$6:$F$505,"Block A",'Phản ánh'!$G$6:$G$505,$B65,'Phản ánh'!$V$6:$V$505,"<>Đã xử lý",'Phản ánh'!$J$6:$J$505,"Cao"))>0,-COUNTIFS('Phản ánh'!$F$6:$F$505,"Block A",'Phản ánh'!$G$6:$G$505,$B65,'Phản ánh'!$V$6:$V$505,"<>Đã xử lý"),COUNTIFS('Phản ánh'!$F$6:$F$505,"Block A",'Phản ánh'!$G$6:$G$505,$B65,'Phản ánh'!$V$6:$V$505,"<>Đã xử lý")),IF(COUNTIFS('Kế hoạch'!$E$6:$E$305,"Block A",'Kế hoạch'!$F$6:$F$305,$B65,'Kế hoạch'!$AO$6:$AO$305,1)>0,"CV","")) | H65: =IF(COUNTIFS('Phản ánh'!$F$6:$F$505,"Block B",'Phản ánh'!$G$6:$G$505,$B65,'Phản ánh'!$V$6:$V$505,"<>Đã xử lý")>0,IF((COUNTIFS('Phản ánh'!$F$6:$F$505,"Block B",'Phản ánh'!$G$6:$G$505,$B65,'Phản ánh'!$V$6:$V$505,"<>Đã xử lý",'Phản ánh'!$J$6:$J$505,"Khẩn cấp")+COUNTIFS('Phản ánh'!$F$6:$F$505,"Block B",'Phản ánh'!$G$6:$G$505,$B65,'Phản ánh'!$V$6:$V$505,"<>Đã xử lý",'Phản ánh'!$J$6:$J$505,"Cao"))>0,-COUNTIFS('Phản ánh'!$F$6:$F$505,"Block B",'Phản ánh'!$G$6:$G$505,$B65,'Phản ánh'!$V$6:$V$505,"<>Đã xử lý"),COUNTIFS('Phản ánh'!$F$6:$F$505,"Block B",'Phản ánh'!$G$6:$G$505,$B65,'Phản ánh'!$V$6:$V$505,"<>Đã xử lý")),IF(COUNTIFS('Kế hoạch'!$E$6:$E$305,"Block B",'Kế hoạch'!$F$6:$F$305,$B65,'Kế hoạch'!$AO$6:$AO$305,1)>0,"CV","")) | L65: =IF(COUNTIFS('Phản ánh'!$F$6:$F$505,"Block C",'Phản ánh'!$G$6:$G$505,$B65,'Phản ánh'!$V$6:$V$505,"<>Đã xử lý")>0,IF((COUNTIFS('Phản ánh'!$F$6:$F$505,"Block C",'Phản ánh'!$G$6:$G$505,$B65,'Phản ánh'!$V$6:$V$505,"<>Đã xử lý",'Phản ánh'!$J$6:$J$505,"Khẩn cấp")+COUNTIFS('Phản ánh'!$F$6:$F$505,"Block C",'Phản ánh'!$G$6:$G$505,$B65,'Phản ánh'!$V$6:$V$505,"<>Đã xử lý",'Phản ánh'!$J$6:$J$505,"Cao"))>0,-COUNTIFS('Phản ánh'!$F$6:$F$505,"Block C",'Phản ánh'!$G$6:$G$505,$B65,'Phản ánh'!$V$6:$V$505,"<>Đã xử lý"),COUNTIFS('Phản ánh'!$F$6:$F$505,"Block C",'Phản ánh'!$G$6:$G$505,$B65,'Phản ánh'!$V$6:$V$505,"<>Đã xử lý")),IF(COUNTIFS('Kế hoạch'!$E$6:$E$305,"Block C",'Kế hoạch'!$F$6:$F$305,$B65,'Kế hoạch'!$AO$6:$AO$305,1)>0,"CV","")) | P65: =IF(COUNTIFS('Phản ánh'!$F$6:$F$505,"Block D",'Phản ánh'!$G$6:$G$505,$B65,'Phản ánh'!$V$6:$V$505,"<>Đã xử lý")>0,IF((COUNTIFS('Phản ánh'!$F$6:$F$505,"Block D",'Phản ánh'!$G$6:$G$505,$B65,'Phản ánh'!$V$6:$V$505,"<>Đã xử lý",'Phản ánh'!$J$6:$J$505,"Khẩn cấp")+COUNTIFS('Phản ánh'!$F$6:$F$505,"Block D",'Phản ánh'!$G$6:$G$505,$B65,'Phản ánh'!$V$6:$V$505,"<>Đã xử lý",'Phản ánh'!$J$6:$J$505,"Cao"))>0,-COUNTIFS('Phản ánh'!$F$6:$F$505,"Block D",'Phản ánh'!$G$6:$G$505,$B65,'Phản ánh'!$V$6:$V$505,"<>Đã xử lý"),COUNTIFS('Phản ánh'!$F$6:$F$505,"Block D",'Phản ánh'!$G$6:$G$505,$B65,'Phản ánh'!$V$6:$V$505,"<>Đã xử lý")),IF(COUNTIFS('Kế hoạch'!$E$6:$E$305,"Block D",'Kế hoạch'!$F$6:$F$305,$B65,'Kế hoạch'!$AO$6:$AO$305,1)>0,"CV","")) | T65: =IF(COUNTIFS('Phản ánh'!$F$6:$F$505,"Block E",'Phản ánh'!$G$6:$G$505,$B65,'Phản ánh'!$V$6:$V$505,"<>Đã xử lý")>0,IF((COUNTIFS('Phản ánh'!$F$6:$F$505,"Block E",'Phản ánh'!$G$6:$G$505,$B65,'Phản ánh'!$V$6:$V$505,"<>Đã xử lý",'Phản ánh'!$J$6:$J$505,"Khẩn cấp")+COUNTIFS('Phản ánh'!$F$6:$F$505,"Block E",'Phản ánh'!$G$6:$G$505,$B65,'Phản ánh'!$V$6:$V$505,"<>Đã xử lý",'Phản ánh'!$J$6:$J$505,"Cao"))>0,-COUNTIFS('Phản ánh'!$F$6:$F$505,"Block E",'Phản ánh'!$G$6:$G$505,$B65,'Phản ánh'!$V$6:$V$505,"<>Đã xử lý"),COUNTIFS('Phản ánh'!$F$6:$F$505,"Block E",'Phản ánh'!$G$6:$G$505,$B65,'Phản ánh'!$V$6:$V$505,"<>Đã xử lý")),IF(COUNTIFS('Kế hoạch'!$E$6:$E$305,"Block E",'Kế hoạch'!$F$6:$F$305,$B65,'Kế hoạch'!$AO$6:$AO$305,1)>0,"CV","")) | X65: =IF(COUNTIFS('Phản ánh'!$F$6:$F$505,"Block G",'Phản ánh'!$G$6:$G$505,$B65,'Phản ánh'!$V$6:$V$505,"<>Đã xử lý")>0,IF((COUNTIFS('Phản ánh'!$F$6:$F$505,"Block G",'Phản ánh'!$G$6:$G$505,$B65,'Phản ánh'!$V$6:$V$505,"<>Đã xử lý",'Phản ánh'!$J$6:$J$505,"Khẩn cấp")+COUNTIFS('Phản ánh'!$F$6:$F$505,"Block G",'Phản ánh'!$G$6:$G$505,$B65,'Phản ánh'!$V$6:$V$505,"<>Đã xử lý",'Phản ánh'!$J$6:$J$505,"Cao"))>0,-COUNTIFS('Phản ánh'!$F$6:$F$505,"Block G",'Phản ánh'!$G$6:$G$505,$B65,'Phản ánh'!$V$6:$V$505,"<>Đã xử lý"),COUNTIFS('Phản ánh'!$F$6:$F$505,"Block G",'Phản ánh'!$G$6:$G$505,$B65,'Phản ánh'!$V$6:$V$505,"<>Đã xử lý")),IF(COUNTIFS('Kế hoạch'!$E$6:$E$305,"Block G",'Kế hoạch'!$F$6:$F$305,$B65,'Kế hoạch'!$AO$6:$AO$305,1)>0,"CV","")) | AB65: Block C | AG65: =COUNTIFS('Phản ánh'!$F$6:$F$505,$AB65,'Phản ánh'!$V$6:$V$505,"<>Đã xử lý") | AI65: =COUNTIFS('Kế hoạch'!$E$6:$E$305,$AB65,'Kế hoạch'!$AO$6:$AO$305,1,'Kế hoạch'!$AR$6:$AR$305,0) | AK65: =COUNTIFS('Phản ánh'!$F$6:$F$505,$AB65,'Phản ánh'!$Y$6:$Y$505,"Quá hạn")+COUNTIFS('Kế hoạch'!$E$6:$E$305,$AB65,'Kế hoạch'!$AD$6:$AD$305,"Quá hạn") | AM65: =IF(AK65>0,"Cần xử lý",IF(AG65+AI65>0,"Theo dõi","Ổn định"))
B66: 20 | D66: =IF(COUNTIFS('Phản ánh'!$F$6:$F$505,"Block A",'Phản ánh'!$G$6:$G$505,$B66,'Phản ánh'!$V$6:$V$505,"<>Đã xử lý")>0,IF((COUNTIFS('Phản ánh'!$F$6:$F$505,"Block A",'Phản ánh'!$G$6:$G$505,$B66,'Phản ánh'!$V$6:$V$505,"<>Đã xử lý",'Phản ánh'!$J$6:$J$505,"Khẩn cấp")+COUNTIFS('Phản ánh'!$F$6:$F$505,"Block A",'Phản ánh'!$G$6:$G$505,$B66,'Phản ánh'!$V$6:$V$505,"<>Đã xử lý",'Phản ánh'!$J$6:$J$505,"Cao"))>0,-COUNTIFS('Phản ánh'!$F$6:$F$505,"Block A",'Phản ánh'!$G$6:$G$505,$B66,'Phản ánh'!$V$6:$V$505,"<>Đã xử lý"),COUNTIFS('Phản ánh'!$F$6:$F$505,"Block A",'Phản ánh'!$G$6:$G$505,$B66,'Phản ánh'!$V$6:$V$505,"<>Đã xử lý")),IF(COUNTIFS('Kế hoạch'!$E$6:$E$305,"Block A",'Kế hoạch'!$F$6:$F$305,$B66,'Kế hoạch'!$AO$6:$AO$305,1)>0,"CV","")) | H66: =IF(COUNTIFS('Phản ánh'!$F$6:$F$505,"Block B",'Phản ánh'!$G$6:$G$505,$B66,'Phản ánh'!$V$6:$V$505,"<>Đã xử lý")>0,IF((COUNTIFS('Phản ánh'!$F$6:$F$505,"Block B",'Phản ánh'!$G$6:$G$505,$B66,'Phản ánh'!$V$6:$V$505,"<>Đã xử lý",'Phản ánh'!$J$6:$J$505,"Khẩn cấp")+COUNTIFS('Phản ánh'!$F$6:$F$505,"Block B",'Phản ánh'!$G$6:$G$505,$B66,'Phản ánh'!$V$6:$V$505,"<>Đã xử lý",'Phản ánh'!$J$6:$J$505,"Cao"))>0,-COUNTIFS('Phản ánh'!$F$6:$F$505,"Block B",'Phản ánh'!$G$6:$G$505,$B66,'Phản ánh'!$V$6:$V$505,"<>Đã xử lý"),COUNTIFS('Phản ánh'!$F$6:$F$505,"Block B",'Phản ánh'!$G$6:$G$505,$B66,'Phản ánh'!$V$6:$V$505,"<>Đã xử lý")),IF(COUNTIFS('Kế hoạch'!$E$6:$E$305,"Block B",'Kế hoạch'!$F$6:$F$305,$B66,'Kế hoạch'!$AO$6:$AO$305,1)>0,"CV","")) | L66: =IF(COUNTIFS('Phản ánh'!$F$6:$F$505,"Block C",'Phản ánh'!$G$6:$G$505,$B66,'Phản ánh'!$V$6:$V$505,"<>Đã xử lý")>0,IF((COUNTIFS('Phản ánh'!$F$6:$F$505,"Block C",'Phản ánh'!$G$6:$G$505,$B66,'Phản ánh'!$V$6:$V$505,"<>Đã xử lý",'Phản ánh'!$J$6:$J$505,"Khẩn cấp")+COUNTIFS('Phản ánh'!$F$6:$F$505,"Block C",'Phản ánh'!$G$6:$G$505,$B66,'Phản ánh'!$V$6:$V$505,"<>Đã xử lý",'Phản ánh'!$J$6:$J$505,"Cao"))>0,-COUNTIFS('Phản ánh'!$F$6:$F$505,"Block C",'Phản ánh'!$G$6:$G$505,$B66,'Phản ánh'!$V$6:$V$505,"<>Đã xử lý"),COUNTIFS('Phản ánh'!$F$6:$F$505,"Block C",'Phản ánh'!$G$6:$G$505,$B66,'Phản ánh'!$V$6:$V$505,"<>Đã xử lý")),IF(COUNTIFS('Kế hoạch'!$E$6:$E$305,"Block C",'Kế hoạch'!$F$6:$F$305,$B66,'Kế hoạch'!$AO$6:$AO$305,1)>0,"CV","")) | P66: =IF(COUNTIFS('Phản ánh'!$F$6:$F$505,"Block D",'Phản ánh'!$G$6:$G$505,$B66,'Phản ánh'!$V$6:$V$505,"<>Đã xử lý")>0,IF((COUNTIFS('Phản ánh'!$F$6:$F$505,"Block D",'Phản ánh'!$G$6:$G$505,$B66,'Phản ánh'!$V$6:$V$505,"<>Đã xử lý",'Phản ánh'!$J$6:$J$505,"Khẩn cấp")+COUNTIFS('Phản ánh'!$F$6:$F$505,"Block D",'Phản ánh'!$G$6:$G$505,$B66,'Phản ánh'!$V$6:$V$505,"<>Đã xử lý",'Phản ánh'!$J$6:$J$505,"Cao"))>0,-COUNTIFS('Phản ánh'!$F$6:$F$505,"Block D",'Phản ánh'!$G$6:$G$505,$B66,'Phản ánh'!$V$6:$V$505,"<>Đã xử lý"),COUNTIFS('Phản ánh'!$F$6:$F$505,"Block D",'Phản ánh'!$G$6:$G$505,$B66,'Phản ánh'!$V$6:$V$505,"<>Đã xử lý")),IF(COUNTIFS('Kế hoạch'!$E$6:$E$305,"Block D",'Kế hoạch'!$F$6:$F$305,$B66,'Kế hoạch'!$AO$6:$AO$305,1)>0,"CV","")) | T66: =IF(COUNTIFS('Phản ánh'!$F$6:$F$505,"Block E",'Phản ánh'!$G$6:$G$505,$B66,'Phản ánh'!$V$6:$V$505,"<>Đã xử lý")>0,IF((COUNTIFS('Phản ánh'!$F$6:$F$505,"Block E",'Phản ánh'!$G$6:$G$505,$B66,'Phản ánh'!$V$6:$V$505,"<>Đã xử lý",'Phản ánh'!$J$6:$J$505,"Khẩn cấp")+COUNTIFS('Phản ánh'!$F$6:$F$505,"Block E",'Phản ánh'!$G$6:$G$505,$B66,'Phản ánh'!$V$6:$V$505,"<>Đã xử lý",'Phản ánh'!$J$6:$J$505,"Cao"))>0,-COUNTIFS('Phản ánh'!$F$6:$F$505,"Block E",'Phản ánh'!$G$6:$G$505,$B66,'Phản ánh'!$V$6:$V$505,"<>Đã xử lý"),COUNTIFS('Phản ánh'!$F$6:$F$505,"Block E",'Phản ánh'!$G$6:$G$505,$B66,'Phản ánh'!$V$6:$V$505,"<>Đã xử lý")),IF(COUNTIFS('Kế hoạch'!$E$6:$E$305,"Block E",'Kế hoạch'!$F$6:$F$305,$B66,'Kế hoạch'!$AO$6:$AO$305,1)>0,"CV","")) | X66: =IF(COUNTIFS('Phản ánh'!$F$6:$F$505,"Block G",'Phản ánh'!$G$6:$G$505,$B66,'Phản ánh'!$V$6:$V$505,"<>Đã xử lý")>0,IF((COUNTIFS('Phản ánh'!$F$6:$F$505,"Block G",'Phản ánh'!$G$6:$G$505,$B66,'Phản ánh'!$V$6:$V$505,"<>Đã xử lý",'Phản ánh'!$J$6:$J$505,"Khẩn cấp")+COUNTIFS('Phản ánh'!$F$6:$F$505,"Block G",'Phản ánh'!$G$6:$G$505,$B66,'Phản ánh'!$V$6:$V$505,"<>Đã xử lý",'Phản ánh'!$J$6:$J$505,"Cao"))>0,-COUNTIFS('Phản ánh'!$F$6:$F$505,"Block G",'Phản ánh'!$G$6:$G$505,$B66,'Phản ánh'!$V$6:$V$505,"<>Đã xử lý"),COUNTIFS('Phản ánh'!$F$6:$F$505,"Block G",'Phản ánh'!$G$6:$G$505,$B66,'Phản ánh'!$V$6:$V$505,"<>Đã xử lý")),IF(COUNTIFS('Kế hoạch'!$E$6:$E$305,"Block G",'Kế hoạch'!$F$6:$F$305,$B66,'Kế hoạch'!$AO$6:$AO$305,1)>0,"CV","")) | AB66: Block D | AG66: =COUNTIFS('Phản ánh'!$F$6:$F$505,$AB66,'Phản ánh'!$V$6:$V$505,"<>Đã xử lý") | AI66: =COUNTIFS('Kế hoạch'!$E$6:$E$305,$AB66,'Kế hoạch'!$AO$6:$AO$305,1,'Kế hoạch'!$AR$6:$AR$305,0) | AK66: =COUNTIFS('Phản ánh'!$F$6:$F$505,$AB66,'Phản ánh'!$Y$6:$Y$505,"Quá hạn")+COUNTIFS('Kế hoạch'!$E$6:$E$305,$AB66,'Kế hoạch'!$AD$6:$AD$305,"Quá hạn") | AM66: =IF(AK66>0,"Cần xử lý",IF(AG66+AI66>0,"Theo dõi","Ổn định"))
B67: 19 | D67: =IF(COUNTIFS('Phản ánh'!$F$6:$F$505,"Block A",'Phản ánh'!$G$6:$G$505,$B67,'Phản ánh'!$V$6:$V$505,"<>Đã xử lý")>0,IF((COUNTIFS('Phản ánh'!$F$6:$F$505,"Block A",'Phản ánh'!$G$6:$G$505,$B67,'Phản ánh'!$V$6:$V$505,"<>Đã xử lý",'Phản ánh'!$J$6:$J$505,"Khẩn cấp")+COUNTIFS('Phản ánh'!$F$6:$F$505,"Block A",'Phản ánh'!$G$6:$G$505,$B67,'Phản ánh'!$V$6:$V$505,"<>Đã xử lý",'Phản ánh'!$J$6:$J$505,"Cao"))>0,-COUNTIFS('Phản ánh'!$F$6:$F$505,"Block A",'Phản ánh'!$G$6:$G$505,$B67,'Phản ánh'!$V$6:$V$505,"<>Đã xử lý"),COUNTIFS('Phản ánh'!$F$6:$F$505,"Block A",'Phản ánh'!$G$6:$G$505,$B67,'Phản ánh'!$V$6:$V$505,"<>Đã xử lý")),IF(COUNTIFS('Kế hoạch'!$E$6:$E$305,"Block A",'Kế hoạch'!$F$6:$F$305,$B67,'Kế hoạch'!$AO$6:$AO$305,1)>0,"CV","")) | H67: =IF(COUNTIFS('Phản ánh'!$F$6:$F$505,"Block B",'Phản ánh'!$G$6:$G$505,$B67,'Phản ánh'!$V$6:$V$505,"<>Đã xử lý")>0,IF((COUNTIFS('Phản ánh'!$F$6:$F$505,"Block B",'Phản ánh'!$G$6:$G$505,$B67,'Phản ánh'!$V$6:$V$505,"<>Đã xử lý",'Phản ánh'!$J$6:$J$505,"Khẩn cấp")+COUNTIFS('Phản ánh'!$F$6:$F$505,"Block B",'Phản ánh'!$G$6:$G$505,$B67,'Phản ánh'!$V$6:$V$505,"<>Đã xử lý",'Phản ánh'!$J$6:$J$505,"Cao"))>0,-COUNTIFS('Phản ánh'!$F$6:$F$505,"Block B",'Phản ánh'!$G$6:$G$505,$B67,'Phản ánh'!$V$6:$V$505,"<>Đã xử lý"),COUNTIFS('Phản ánh'!$F$6:$F$505,"Block B",'Phản ánh'!$G$6:$G$505,$B67,'Phản ánh'!$V$6:$V$505,"<>Đã xử lý")),IF(COUNTIFS('Kế hoạch'!$E$6:$E$305,"Block B",'Kế hoạch'!$F$6:$F$305,$B67,'Kế hoạch'!$AO$6:$AO$305,1)>0,"CV","")) | L67: =IF(COUNTIFS('Phản ánh'!$F$6:$F$505,"Block C",'Phản ánh'!$G$6:$G$505,$B67,'Phản ánh'!$V$6:$V$505,"<>Đã xử lý")>0,IF((COUNTIFS('Phản ánh'!$F$6:$F$505,"Block C",'Phản ánh'!$G$6:$G$505,$B67,'Phản ánh'!$V$6:$V$505,"<>Đã xử lý",'Phản ánh'!$J$6:$J$505,"Khẩn cấp")+COUNTIFS('Phản ánh'!$F$6:$F$505,"Block C",'Phản ánh'!$G$6:$G$505,$B67,'Phản ánh'!$V$6:$V$505,"<>Đã xử lý",'Phản ánh'!$J$6:$J$505,"Cao"))>0,-COUNTIFS('Phản ánh'!$F$6:$F$505,"Block C",'Phản ánh'!$G$6:$G$505,$B67,'Phản ánh'!$V$6:$V$505,"<>Đã xử lý"),COUNTIFS('Phản ánh'!$F$6:$F$505,"Block C",'Phản ánh'!$G$6:$G$505,$B67,'Phản ánh'!$V$6:$V$505,"<>Đã xử lý")),IF(COUNTIFS('Kế hoạch'!$E$6:$E$305,"Block C",'Kế hoạch'!$F$6:$F$305,$B67,'Kế hoạch'!$AO$6:$AO$305,1)>0,"CV","")) | P67: =IF(COUNTIFS('Phản ánh'!$F$6:$F$505,"Block D",'Phản ánh'!$G$6:$G$505,$B67,'Phản ánh'!$V$6:$V$505,"<>Đã xử lý")>0,IF((COUNTIFS('Phản ánh'!$F$6:$F$505,"Block D",'Phản ánh'!$G$6:$G$505,$B67,'Phản ánh'!$V$6:$V$505,"<>Đã xử lý",'Phản ánh'!$J$6:$J$505,"Khẩn cấp")+COUNTIFS('Phản ánh'!$F$6:$F$505,"Block D",'Phản ánh'!$G$6:$G$505,$B67,'Phản ánh'!$V$6:$V$505,"<>Đã xử lý",'Phản ánh'!$J$6:$J$505,"Cao"))>0,-COUNTIFS('Phản ánh'!$F$6:$F$505,"Block D",'Phản ánh'!$G$6:$G$505,$B67,'Phản ánh'!$V$6:$V$505,"<>Đã xử lý"),COUNTIFS('Phản ánh'!$F$6:$F$505,"Block D",'Phản ánh'!$G$6:$G$505,$B67,'Phản ánh'!$V$6:$V$505,"<>Đã xử lý")),IF(COUNTIFS('Kế hoạch'!$E$6:$E$305,"Block D",'Kế hoạch'!$F$6:$F$305,$B67,'Kế hoạch'!$AO$6:$AO$305,1)>0,"CV","")) | T67: =IF(COUNTIFS('Phản ánh'!$F$6:$F$505,"Block E",'Phản ánh'!$G$6:$G$505,$B67,'Phản ánh'!$V$6:$V$505,"<>Đã xử lý")>0,IF((COUNTIFS('Phản ánh'!$F$6:$F$505,"Block E",'Phản ánh'!$G$6:$G$505,$B67,'Phản ánh'!$V$6:$V$505,"<>Đã xử lý",'Phản ánh'!$J$6:$J$505,"Khẩn cấp")+COUNTIFS('Phản ánh'!$F$6:$F$505,"Block E",'Phản ánh'!$G$6:$G$505,$B67,'Phản ánh'!$V$6:$V$505,"<>Đã xử lý",'Phản ánh'!$J$6:$J$505,"Cao"))>0,-COUNTIFS('Phản ánh'!$F$6:$F$505,"Block E",'Phản ánh'!$G$6:$G$505,$B67,'Phản ánh'!$V$6:$V$505,"<>Đã xử lý"),COUNTIFS('Phản ánh'!$F$6:$F$505,"Block E",'Phản ánh'!$G$6:$G$505,$B67,'Phản ánh'!$V$6:$V$505,"<>Đã xử lý")),IF(COUNTIFS('Kế hoạch'!$E$6:$E$305,"Block E",'Kế hoạch'!$F$6:$F$305,$B67,'Kế hoạch'!$AO$6:$AO$305,1)>0,"CV","")) | X67: =IF(COUNTIFS('Phản ánh'!$F$6:$F$505,"Block G",'Phản ánh'!$G$6:$G$505,$B67,'Phản ánh'!$V$6:$V$505,"<>Đã xử lý")>0,IF((COUNTIFS('Phản ánh'!$F$6:$F$505,"Block G",'Phản ánh'!$G$6:$G$505,$B67,'Phản ánh'!$V$6:$V$505,"<>Đã xử lý",'Phản ánh'!$J$6:$J$505,"Khẩn cấp")+COUNTIFS('Phản ánh'!$F$6:$F$505,"Block G",'Phản ánh'!$G$6:$G$505,$B67,'Phản ánh'!$V$6:$V$505,"<>Đã xử lý",'Phản ánh'!$J$6:$J$505,"Cao"))>0,-COUNTIFS('Phản ánh'!$F$6:$F$505,"Block G",'Phản ánh'!$G$6:$G$505,$B67,'Phản ánh'!$V$6:$V$505,"<>Đã xử lý"),COUNTIFS('Phản ánh'!$F$6:$F$505,"Block G",'Phản ánh'!$G$6:$G$505,$B67,'Phản ánh'!$V$6:$V$505,"<>Đã xử lý")),IF(COUNTIFS('Kế hoạch'!$E$6:$E$305,"Block G",'Kế hoạch'!$F$6:$F$305,$B67,'Kế hoạch'!$AO$6:$AO$305,1)>0,"CV","")) | AB67: Block E | AG67: =COUNTIFS('Phản ánh'!$F$6:$F$505,$AB67,'Phản ánh'!$V$6:$V$505,"<>Đã xử lý") | AI67: =COUNTIFS('Kế hoạch'!$E$6:$E$305,$AB67,'Kế hoạch'!$AO$6:$AO$305,1,'Kế hoạch'!$AR$6:$AR$305,0) | AK67: =COUNTIFS('Phản ánh'!$F$6:$F$505,$AB67,'Phản ánh'!$Y$6:$Y$505,"Quá hạn")+COUNTIFS('Kế hoạch'!$E$6:$E$305,$AB67,'Kế hoạch'!$AD$6:$AD$305,"Quá hạn") | AM67: =IF(AK67>0,"Cần xử lý",IF(AG67+AI67>0,"Theo dõi","Ổn định"))
B68: 18 | D68: =IF(COUNTIFS('Phản ánh'!$F$6:$F$505,"Block A",'Phản ánh'!$G$6:$G$505,$B68,'Phản ánh'!$V$6:$V$505,"<>Đã xử lý")>0,IF((COUNTIFS('Phản ánh'!$F$6:$F$505,"Block A",'Phản ánh'!$G$6:$G$505,$B68,'Phản ánh'!$V$6:$V$505,"<>Đã xử lý",'Phản ánh'!$J$6:$J$505,"Khẩn cấp")+COUNTIFS('Phản ánh'!$F$6:$F$505,"Block A",'Phản ánh'!$G$6:$G$505,$B68,'Phản ánh'!$V$6:$V$505,"<>Đã xử lý",'Phản ánh'!$J$6:$J$505,"Cao"))>0,-COUNTIFS('Phản ánh'!$F$6:$F$505,"Block A",'Phản ánh'!$G$6:$G$505,$B68,'Phản ánh'!$V$6:$V$505,"<>Đã xử lý"),COUNTIFS('Phản ánh'!$F$6:$F$505,"Block A",'Phản ánh'!$G$6:$G$505,$B68,'Phản ánh'!$V$6:$V$505,"<>Đã xử lý")),IF(COUNTIFS('Kế hoạch'!$E$6:$E$305,"Block A",'Kế hoạch'!$F$6:$F$305,$B68,'Kế hoạch'!$AO$6:$AO$305,1)>0,"CV","")) | H68: =IF(COUNTIFS('Phản ánh'!$F$6:$F$505,"Block B",'Phản ánh'!$G$6:$G$505,$B68,'Phản ánh'!$V$6:$V$505,"<>Đã xử lý")>0,IF((COUNTIFS('Phản ánh'!$F$6:$F$505,"Block B",'Phản ánh'!$G$6:$G$505,$B68,'Phản ánh'!$V$6:$V$505,"<>Đã xử lý",'Phản ánh'!$J$6:$J$505,"Khẩn cấp")+COUNTIFS('Phản ánh'!$F$6:$F$505,"Block B",'Phản ánh'!$G$6:$G$505,$B68,'Phản ánh'!$V$6:$V$505,"<>Đã xử lý",'Phản ánh'!$J$6:$J$505,"Cao"))>0,-COUNTIFS('Phản ánh'!$F$6:$F$505,"Block B",'Phản ánh'!$G$6:$G$505,$B68,'Phản ánh'!$V$6:$V$505,"<>Đã xử lý"),COUNTIFS('Phản ánh'!$F$6:$F$505,"Block B",'Phản ánh'!$G$6:$G$505,$B68,'Phản ánh'!$V$6:$V$505,"<>Đã xử lý")),IF(COUNTIFS('Kế hoạch'!$E$6:$E$305,"Block B",'Kế hoạch'!$F$6:$F$305,$B68,'Kế hoạch'!$AO$6:$AO$305,1)>0,"CV","")) | L68: =IF(COUNTIFS('Phản ánh'!$F$6:$F$505,"Block C",'Phản ánh'!$G$6:$G$505,$B68,'Phản ánh'!$V$6:$V$505,"<>Đã xử lý")>0,IF((COUNTIFS('Phản ánh'!$F$6:$F$505,"Block C",'Phản ánh'!$G$6:$G$505,$B68,'Phản ánh'!$V$6:$V$505,"<>Đã xử lý",'Phản ánh'!$J$6:$J$505,"Khẩn cấp")+COUNTIFS('Phản ánh'!$F$6:$F$505,"Block C",'Phản ánh'!$G$6:$G$505,$B68,'Phản ánh'!$V$6:$V$505,"<>Đã xử lý",'Phản ánh'!$J$6:$J$505,"Cao"))>0,-COUNTIFS('Phản ánh'!$F$6:$F$505,"Block C",'Phản ánh'!$G$6:$G$505,$B68,'Phản ánh'!$V$6:$V$505,"<>Đã xử lý"),COUNTIFS('Phản ánh'!$F$6:$F$505,"Block C",'Phản ánh'!$G$6:$G$505,$B68,'Phản ánh'!$V$6:$V$505,"<>Đã xử lý")),IF(COUNTIFS('Kế hoạch'!$E$6:$E$305,"Block C",'Kế hoạch'!$F$6:$F$305,$B68,'Kế hoạch'!$AO$6:$AO$305,1)>0,"CV","")) | P68: =IF(COUNTIFS('Phản ánh'!$F$6:$F$505,"Block D",'Phản ánh'!$G$6:$G$505,$B68,'Phản ánh'!$V$6:$V$505,"<>Đã xử lý")>0,IF((COUNTIFS('Phản ánh'!$F$6:$F$505,"Block D",'Phản ánh'!$G$6:$G$505,$B68,'Phản ánh'!$V$6:$V$505,"<>Đã xử lý",'Phản ánh'!$J$6:$J$505,"Khẩn cấp")+COUNTIFS('Phản ánh'!$F$6:$F$505,"Block D",'Phản ánh'!$G$6:$G$505,$B68,'Phản ánh'!$V$6:$V$505,"<>Đã xử lý",'Phản ánh'!$J$6:$J$505,"Cao"))>0,-COUNTIFS('Phản ánh'!$F$6:$F$505,"Block D",'Phản ánh'!$G$6:$G$505,$B68,'Phản ánh'!$V$6:$V$505,"<>Đã xử lý"),COUNTIFS('Phản ánh'!$F$6:$F$505,"Block D",'Phản ánh'!$G$6:$G$505,$B68,'Phản ánh'!$V$6:$V$505,"<>Đã xử lý")),IF(COUNTIFS('Kế hoạch'!$E$6:$E$305,"Block D",'Kế hoạch'!$F$6:$F$305,$B68,'Kế hoạch'!$AO$6:$AO$305,1)>0,"CV","")) | T68: =IF(COUNTIFS('Phản ánh'!$F$6:$F$505,"Block E",'Phản ánh'!$G$6:$G$505,$B68,'Phản ánh'!$V$6:$V$505,"<>Đã xử lý")>0,IF((COUNTIFS('Phản ánh'!$F$6:$F$505,"Block E",'Phản ánh'!$G$6:$G$505,$B68,'Phản ánh'!$V$6:$V$505,"<>Đã xử lý",'Phản ánh'!$J$6:$J$505,"Khẩn cấp")+COUNTIFS('Phản ánh'!$F$6:$F$505,"Block E",'Phản ánh'!$G$6:$G$505,$B68,'Phản ánh'!$V$6:$V$505,"<>Đã xử lý",'Phản ánh'!$J$6:$J$505,"Cao"))>0,-COUNTIFS('Phản ánh'!$F$6:$F$505,"Block E",'Phản ánh'!$G$6:$G$505,$B68,'Phản ánh'!$V$6:$V$505,"<>Đã xử lý"),COUNTIFS('Phản ánh'!$F$6:$F$505,"Block E",'Phản ánh'!$G$6:$G$505,$B68,'Phản ánh'!$V$6:$V$505,"<>Đã xử lý")),IF(COUNTIFS('Kế hoạch'!$E$6:$E$305,"Block E",'Kế hoạch'!$F$6:$F$305,$B68,'Kế hoạch'!$AO$6:$AO$305,1)>0,"CV","")) | X68: =IF(COUNTIFS('Phản ánh'!$F$6:$F$505,"Block G",'Phản ánh'!$G$6:$G$505,$B68,'Phản ánh'!$V$6:$V$505,"<>Đã xử lý")>0,IF((COUNTIFS('Phản ánh'!$F$6:$F$505,"Block G",'Phản ánh'!$G$6:$G$505,$B68,'Phản ánh'!$V$6:$V$505,"<>Đã xử lý",'Phản ánh'!$J$6:$J$505,"Khẩn cấp")+COUNTIFS('Phản ánh'!$F$6:$F$505,"Block G",'Phản ánh'!$G$6:$G$505,$B68,'Phản ánh'!$V$6:$V$505,"<>Đã xử lý",'Phản ánh'!$J$6:$J$505,"Cao"))>0,-COUNTIFS('Phản ánh'!$F$6:$F$505,"Block G",'Phản ánh'!$G$6:$G$505,$B68,'Phản ánh'!$V$6:$V$505,"<>Đã xử lý"),COUNTIFS('Phản ánh'!$F$6:$F$505,"Block G",'Phản ánh'!$G$6:$G$505,$B68,'Phản ánh'!$V$6:$V$505,"<>Đã xử lý")),IF(COUNTIFS('Kế hoạch'!$E$6:$E$305,"Block G",'Kế hoạch'!$F$6:$F$305,$B68,'Kế hoạch'!$AO$6:$AO$305,1)>0,"CV","")) | AB68: Block G | AG68: =COUNTIFS('Phản ánh'!$F$6:$F$505,$AB68,'Phản ánh'!$V$6:$V$505,"<>Đã xử lý") | AI68: =COUNTIFS('Kế hoạch'!$E$6:$E$305,$AB68,'Kế hoạch'!$AO$6:$AO$305,1,'Kế hoạch'!$AR$6:$AR$305,0) | AK68: =COUNTIFS('Phản ánh'!$F$6:$F$505,$AB68,'Phản ánh'!$Y$6:$Y$505,"Quá hạn")+COUNTIFS('Kế hoạch'!$E$6:$E$305,$AB68,'Kế hoạch'!$AD$6:$AD$305,"Quá hạn") | AM68: =IF(AK68>0,"Cần xử lý",IF(AG68+AI68>0,"Theo dõi","Ổn định"))
B69: 17 | D69: =IF(COUNTIFS('Phản ánh'!$F$6:$F$505,"Block A",'Phản ánh'!$G$6:$G$505,$B69,'Phản ánh'!$V$6:$V$505,"<>Đã xử lý")>0,IF((COUNTIFS('Phản ánh'!$F$6:$F$505,"Block A",'Phản ánh'!$G$6:$G$505,$B69,'Phản ánh'!$V$6:$V$505,"<>Đã xử lý",'Phản ánh'!$J$6:$J$505,"Khẩn cấp")+COUNTIFS('Phản ánh'!$F$6:$F$505,"Block A",'Phản ánh'!$G$6:$G$505,$B69,'Phản ánh'!$V$6:$V$505,"<>Đã xử lý",'Phản ánh'!$J$6:$J$505,"Cao"))>0,-COUNTIFS('Phản ánh'!$F$6:$F$505,"Block A",'Phản ánh'!$G$6:$G$505,$B69,'Phản ánh'!$V$6:$V$505,"<>Đã xử lý"),COUNTIFS('Phản ánh'!$F$6:$F$505,"Block A",'Phản ánh'!$G$6:$G$505,$B69,'Phản ánh'!$V$6:$V$505,"<>Đã xử lý")),IF(COUNTIFS('Kế hoạch'!$E$6:$E$305,"Block A",'Kế hoạch'!$F$6:$F$305,$B69,'Kế hoạch'!$AO$6:$AO$305,1)>0,"CV","")) | H69: =IF(COUNTIFS('Phản ánh'!$F$6:$F$505,"Block B",'Phản ánh'!$G$6:$G$505,$B69,'Phản ánh'!$V$6:$V$505,"<>Đã xử lý")>0,IF((COUNTIFS('Phản ánh'!$F$6:$F$505,"Block B",'Phản ánh'!$G$6:$G$505,$B69,'Phản ánh'!$V$6:$V$505,"<>Đã xử lý",'Phản ánh'!$J$6:$J$505,"Khẩn cấp")+COUNTIFS('Phản ánh'!$F$6:$F$505,"Block B",'Phản ánh'!$G$6:$G$505,$B69,'Phản ánh'!$V$6:$V$505,"<>Đã xử lý",'Phản ánh'!$J$6:$J$505,"Cao"))>0,-COUNTIFS('Phản ánh'!$F$6:$F$505,"Block B",'Phản ánh'!$G$6:$G$505,$B69,'Phản ánh'!$V$6:$V$505,"<>Đã xử lý"),COUNTIFS('Phản ánh'!$F$6:$F$505,"Block B",'Phản ánh'!$G$6:$G$505,$B69,'Phản ánh'!$V$6:$V$505,"<>Đã xử lý")),IF(COUNTIFS('Kế hoạch'!$E$6:$E$305,"Block B",'Kế hoạch'!$F$6:$F$305,$B69,'Kế hoạch'!$AO$6:$AO$305,1)>0,"CV","")) | L69: =IF(COUNTIFS('Phản ánh'!$F$6:$F$505,"Block C",'Phản ánh'!$G$6:$G$505,$B69,'Phản ánh'!$V$6:$V$505,"<>Đã xử lý")>0,IF((COUNTIFS('Phản ánh'!$F$6:$F$505,"Block C",'Phản ánh'!$G$6:$G$505,$B69,'Phản ánh'!$V$6:$V$505,"<>Đã xử lý",'Phản ánh'!$J$6:$J$505,"Khẩn cấp")+COUNTIFS('Phản ánh'!$F$6:$F$505,"Block C",'Phản ánh'!$G$6:$G$505,$B69,'Phản ánh'!$V$6:$V$505,"<>Đã xử lý",'Phản ánh'!$J$6:$J$505,"Cao"))>0,-COUNTIFS('Phản ánh'!$F$6:$F$505,"Block C",'Phản ánh'!$G$6:$G$505,$B69,'Phản ánh'!$V$6:$V$505,"<>Đã xử lý"),COUNTIFS('Phản ánh'!$F$6:$F$505,"Block C",'Phản ánh'!$G$6:$G$505,$B69,'Phản ánh'!$V$6:$V$505,"<>Đã xử lý")),IF(COUNTIFS('Kế hoạch'!$E$6:$E$305,"Block C",'Kế hoạch'!$F$6:$F$305,$B69,'Kế hoạch'!$AO$6:$AO$305,1)>0,"CV","")) | P69: =IF(COUNTIFS('Phản ánh'!$F$6:$F$505,"Block D",'Phản ánh'!$G$6:$G$505,$B69,'Phản ánh'!$V$6:$V$505,"<>Đã xử lý")>0,IF((COUNTIFS('Phản ánh'!$F$6:$F$505,"Block D",'Phản ánh'!$G$6:$G$505,$B69,'Phản ánh'!$V$6:$V$505,"<>Đã xử lý",'Phản ánh'!$J$6:$J$505,"Khẩn cấp")+COUNTIFS('Phản ánh'!$F$6:$F$505,"Block D",'Phản ánh'!$G$6:$G$505,$B69,'Phản ánh'!$V$6:$V$505,"<>Đã xử lý",'Phản ánh'!$J$6:$J$505,"Cao"))>0,-COUNTIFS('Phản ánh'!$F$6:$F$505,"Block D",'Phản ánh'!$G$6:$G$505,$B69,'Phản ánh'!$V$6:$V$505,"<>Đã xử lý"),COUNTIFS('Phản ánh'!$F$6:$F$505,"Block D",'Phản ánh'!$G$6:$G$505,$B69,'Phản ánh'!$V$6:$V$505,"<>Đã xử lý")),IF(COUNTIFS('Kế hoạch'!$E$6:$E$305,"Block D",'Kế hoạch'!$F$6:$F$305,$B69,'Kế hoạch'!$AO$6:$AO$305,1)>0,"CV","")) | T69: =IF(COUNTIFS('Phản ánh'!$F$6:$F$505,"Block E",'Phản ánh'!$G$6:$G$505,$B69,'Phản ánh'!$V$6:$V$505,"<>Đã xử lý")>0,IF((COUNTIFS('Phản ánh'!$F$6:$F$505,"Block E",'Phản ánh'!$G$6:$G$505,$B69,'Phản ánh'!$V$6:$V$505,"<>Đã xử lý",'Phản ánh'!$J$6:$J$505,"Khẩn cấp")+COUNTIFS('Phản ánh'!$F$6:$F$505,"Block E",'Phản ánh'!$G$6:$G$505,$B69,'Phản ánh'!$V$6:$V$505,"<>Đã xử lý",'Phản ánh'!$J$6:$J$505,"Cao"))>0,-COUNTIFS('Phản ánh'!$F$6:$F$505,"Block E",'Phản ánh'!$G$6:$G$505,$B69,'Phản ánh'!$V$6:$V$505,"<>Đã xử lý"),COUNTIFS('Phản ánh'!$F$6:$F$505,"Block E",'Phản ánh'!$G$6:$G$505,$B69,'Phản ánh'!$V$6:$V$505,"<>Đã xử lý")),IF(COUNTIFS('Kế hoạch'!$E$6:$E$305,"Block E",'Kế hoạch'!$F$6:$F$305,$B69,'Kế hoạch'!$AO$6:$AO$305,1)>0,"CV","")) | X69: =IF(COUNTIFS('Phản ánh'!$F$6:$F$505,"Block G",'Phản ánh'!$G$6:$G$505,$B69,'Phản ánh'!$V$6:$V$505,"<>Đã xử lý")>0,IF((COUNTIFS('Phản ánh'!$F$6:$F$505,"Block G",'Phản ánh'!$G$6:$G$505,$B69,'Phản ánh'!$V$6:$V$505,"<>Đã xử lý",'Phản ánh'!$J$6:$J$505,"Khẩn cấp")+COUNTIFS('Phản ánh'!$F$6:$F$505,"Block G",'Phản ánh'!$G$6:$G$505,$B69,'Phản ánh'!$V$6:$V$505,"<>Đã xử lý",'Phản ánh'!$J$6:$J$505,"Cao"))>0,-COUNTIFS('Phản ánh'!$F$6:$F$505,"Block G",'Phản ánh'!$G$6:$G$505,$B69,'Phản ánh'!$V$6:$V$505,"<>Đã xử lý"),COUNTIFS('Phản ánh'!$F$6:$F$505,"Block G",'Phản ánh'!$G$6:$G$505,$B69,'Phản ánh'!$V$6:$V$505,"<>Đã xử lý")),IF(COUNTIFS('Kế hoạch'!$E$6:$E$305,"Block G",'Kế hoạch'!$F$6:$F$305,$B69,'Kế hoạch'!$AO$6:$AO$305,1)>0,"CV","")) | AB69: Cổng 1 | AG69: =COUNTIFS('Phản ánh'!$F$6:$F$505,$AB69,'Phản ánh'!$V$6:$V$505,"<>Đã xử lý") | AI69: =COUNTIFS('Kế hoạch'!$E$6:$E$305,$AB69,'Kế hoạch'!$AO$6:$AO$305,1,'Kế hoạch'!$AR$6:$AR$305,0) | AK69: =COUNTIFS('Phản ánh'!$F$6:$F$505,$AB69,'Phản ánh'!$Y$6:$Y$505,"Quá hạn")+COUNTIFS('Kế hoạch'!$E$6:$E$305,$AB69,'Kế hoạch'!$AD$6:$AD$305,"Quá hạn") | AM69: =IF(AK69>0,"Cần xử lý",IF(AG69+AI69>0,"Theo dõi","Ổn định"))
